Workbook

Sheet PROGRAM
A1: ADDR | B1: MNEM | C1: OP1 | D1: OP2 | E1: OPCODE | F1: ARG1 | G1: ARG2 | H1: HUMAN | K1: Factorial | P1: Sum values | U1: GCD
A2: 0 | B2: LDI | C2: AX | D2: 5 | E2: =CHOOSE(MATCH(B2,{"NOP","LDI","LDR","STR","MOV","ADDI","ADDR","SUBI","SUBR","JMP","JZ","JNZ","MUL","LOOP","AND","HLT","OR","XOR","DIV"},0),0,1,2,3,4,5,6,7,8,9,10,11,12,13,14,15,16,17,18) -> 1 | F2: =IF(C2="AX",0,IF(C2="BX",1,IF(C2="CX",2,IF(C2="DX",3,VALUE(C2))))) -> 0 | G2: =IF(OR(D2="AX",D2="BX",D2="CX",D2="DX"), IF(OR(E2=12,E2=14,E2=16,E2=17,E2=18), IF(D2="AX",128+0,IF(D2="BX",128+1,IF(D2="CX",128+2,128+3))), IF(D2="AX",0,IF(D2="BX",1,IF(D2="CX",2,3))) ), VALUE(D2)) -> 5 | H2: =IF(E2=0,"NOP",IF(E2=1,"LDI "&CHOOSE(F2+1,"AX","BX","CX","DX")&","&G2,IF(E2=2,"LDR "&CHOOSE(F2+1,"AX","BX","CX","DX")&",["&G2&"]",IF(E2=3,"STR ["&F2&"],AX",IF(E2=4,"MOV "&CHOOSE(F2+1,"AX","BX","CX","DX")&","&CHOOSE(G2+1,"AX","BX","CX","DX"),IF(E2=5,"ADDI "&CHOOSE(F2+1,"AX","BX","CX","DX")&","&G2,IF(E2=6,"ADDR "&CHOOSE(F2+1,"AX","BX","CX","DX")&","&CHOOSE(G2+1,"AX","BX","CX","DX"),IF(E2=7,"SUBI "&CHOOSE(F2+1,"AX","BX","CX","DX")&","&G2,IF(E2=8,"SUBR "&CHOOSE(F2+1,"AX","BX","CX","DX")&","&CHOOSE(G2+1,"AX","BX","CX","DX"),IF(E2=9,"JMP "&F2,IF(E2=10,"JZ "&F2,IF(E2=11,"JNZ "&F2,IF(E2=12,"MUL "&CHOOSE(F2+1,"AX","BX","CX","DX")&","&IF(G2>=128,CHOOSE(G2-128+1,"AX","BX","CX","DX"),G2),IF(E2=13,"LOOP "&F2,IF(E2=14,"AND "&CHOOSE(F2+1,"AX","BX","CX","DX")&","&IF(G2>=128,CHOOSE(G2-128+1,"AX","BX","CX","DX"),G2),IF(E2=15,"HLT",IF(E2=16,"OR "&CHOOSE(F2+1,"AX","BX","CX","DX")&","&IF(G2>=128,CHOOSE(G2-128+1,"AX","BX","CX","DX"),G2),IF(E2=17,"XOR "&CHOOSE(F2+1,"AX","BX","CX","DX")&","&IF(G2>=128,CHOOSE(G2-128+1,"AX","BX","CX","DX"),G2),IF(E2=18,"DIV AX,"&IF(G2>=128,CHOOSE(G2-128+1,"AX","BX","CX","DX"),G2),"???"))))))))))))))))))) -> LDI AX,5 | K2: LDR | L2: CX | M2: 10 | P2: LDR | Q2: CX | R2: 10 | U2: LDR | V2: AX | W2: 1
A3: 1 | B3: LDR | C3: BX | D3: 7 | E3: =CHOOSE(MATCH(B3,{"NOP","LDI","LDR","STR","MOV","ADDI","ADDR","SUBI","SUBR","JMP","JZ","JNZ","MUL","LOOP","AND","HLT","OR","XOR","DIV"},0),0,1,2,3,4,5,6,7,8,9,10,11,12,13,14,15,16,17,18) -> 2 | F3: =IF(C3="AX",0,IF(C3="BX",1,IF(C3="CX",2,IF(C3="DX",3,VALUE(C3))))) -> 1 | G3: =IF(OR(D3="AX",D3="BX",D3="CX",D3="DX"), IF(OR(E3=12,E3=14,E3=16,E3=17,E3=18), IF(D3="AX",128+0,IF(D3="BX",128+1,IF(D3="CX",128+2,128+3))), IF(D3="AX",0,IF(D3="BX",1,IF(D3="CX",2,3))) ), VALUE(D3)) -> 7 | H3: =IF(E3=0,"NOP",IF(E3=1,"LDI "&CHOOSE(F3+1,"AX","BX","CX","DX")&","&G3,IF(E3=2,"LDR "&CHOOSE(F3+1,"AX","BX","CX","DX")&",["&G3&"]",IF(E3=3,"STR ["&F3&"],AX",IF(E3=4,"MOV "&CHOOSE(F3+1,"AX","BX","CX","DX")&","&CHOOSE(G3+1,"AX","BX","CX","DX"),IF(E3=5,"ADDI "&CHOOSE(F3+1,"AX","BX","CX","DX")&","&G3,IF(E3=6,"ADDR "&CHOOSE(F3+1,"AX","BX","CX","DX")&","&CHOOSE(G3+1,"AX","BX","CX","DX"),IF(E3=7,"SUBI "&CHOOSE(F3+1,"AX","BX","CX","DX")&","&G3,IF(E3=8,"SUBR "&CHOOSE(F3+1,"AX","BX","CX","DX")&","&CHOOSE(G3+1,"AX","BX","CX","DX"),IF(E3=9,"JMP "&F3,IF(E3=10,"JZ "&F3,IF(E3=11,"JNZ "&F3,IF(E3=12,"MUL "&CHOOSE(F3+1,"AX","BX","CX","DX")&","&IF(G3>=128,CHOOSE(G3-128+1,"AX","BX","CX","DX"),G3),IF(E3=13,"LOOP "&F3,IF(E3=14,"AND "&CHOOSE(F3+1,"AX","BX","CX","DX")&","&IF(G3>=128,CHOOSE(G3-128+1,"AX","BX","CX","DX"),G3),IF(E3=15,"HLT",IF(E3=16,"OR "&CHOOSE(F3+1,"AX","BX","CX","DX")&","&IF(G3>=128,CHOOSE(G3-128+1,"AX","BX","CX","DX"),G3),IF(E3=17,"XOR "&CHOOSE(F3+1,"AX","BX","CX","DX")&","&IF(G3>=128,CHOOSE(G3-128+1,"AX","BX","CX","DX"),G3),IF(E3=18,"DIV AX,"&IF(G3>=128,CHOOSE(G3-128+1,"AX","BX","CX","DX"),G3),"???"))))))))))))))))))) -> LDR BX,[7] | K3: LDI | L3: AX | M3: 1 | P3: LDI | Q3: AX | R3: 0 | U3: LDR | V3: CX | W3: 2
A4: 2 | B4: ADDR | C4: AX | D4: BX | E4: =CHOOSE(MATCH(B4,{"NOP","LDI","LDR","STR","MOV","ADDI","ADDR","SUBI","SUBR","JMP","JZ","JNZ","MUL","LOOP","AND","HLT","OR","XOR","DIV"},0),0,1,2,3,4,5,6,7,8,9,10,11,12,13,14,15,16,17,18) -> 6 | F4: =IF(C4="AX",0,IF(C4="BX",1,IF(C4="CX",2,IF(C4="DX",3,VALUE(C4))))) -> 0 | G4: =IF(OR(D4="AX",D4="BX",D4="CX",D4="DX"), IF(OR(E4=12,E4=14,E4=16,E4=17,E4=18), IF(D4="AX",128+0,IF(D4="BX",128+1,IF(D4="CX",128+2,128+3))), IF(D4="AX",0,IF(D4="BX",1,IF(D4="CX",2,3))) ), VALUE(D4)) -> 1 | H4: =IF(E4=0,"NOP",IF(E4=1,"LDI "&CHOOSE(F4+1,"AX","BX","CX","DX")&","&G4,IF(E4=2,"LDR "&CHOOSE(F4+1,"AX","BX","CX","DX")&",["&G4&"]",IF(E4=3,"STR ["&F4&"],AX",IF(E4=4,"MOV "&CHOOSE(F4+1,"AX","BX","CX","DX")&","&CHOOSE(G4+1,"AX","BX","CX","DX"),IF(E4=5,"ADDI "&CHOOSE(F4+1,"AX","BX","CX","DX")&","&G4,IF(E4=6,"ADDR "&CHOOSE(F4+1,"AX","BX","CX","DX")&","&CHOOSE(G4+1,"AX","BX","CX","DX"),IF(E4=7,"SUBI "&CHOOSE(F4+1,"AX","BX","CX","DX")&","&G4,IF(E4=8,"SUBR "&CHOOSE(F4+1,"AX","BX","CX","DX")&","&CHOOSE(G4+1,"AX","BX","CX","DX"),IF(E4=9,"JMP "&F4,IF(E4=10,"JZ "&F4,IF(E4=11,"JNZ "&F4,IF(E4=12,"MUL "&CHOOSE(F4+1,"AX","BX","CX","DX")&","&IF(G4>=128,CHOOSE(G4-128+1,"AX","BX","CX","DX"),G4),IF(E4=13,"LOOP "&F4,IF(E4=14,"AND "&CHOOSE(F4+1,"AX","BX","CX","DX")&","&IF(G4>=128,CHOOSE(G4-128+1,"AX","BX","CX","DX"),G4),IF(E4=15,"HLT",IF(E4=16,"OR "&CHOOSE(F4+1,"AX","BX","CX","DX")&","&IF(G4>=128,CHOOSE(G4-128+1,"AX","BX","CX","DX"),G4),IF(E4=17,"XOR "&CHOOSE(F4+1,"AX","BX","CX","DX")&","&IF(G4>=128,CHOOSE(G4-128+1,"AX","BX","CX","DX"),G4),IF(E4=18,"DIV AX,"&IF(G4>=128,CHOOSE(G4-128+1,"AX","BX","CX","DX"),G4),"???"))))))))))))))))))) -> ADDR AX,BX | K4: MOV | L4: DX | M4: CX | P4: ADDR | Q4: AX | R4: CX | U4: MOV | V4: DX | W4: CX
A5: 3 | B5: STR | C5: 1 | E5: =CHOOSE(MATCH(B5,{"NOP","LDI","LDR","STR","MOV","ADDI","ADDR","SUBI","SUBR","JMP","JZ","JNZ","MUL","LOOP","AND","HLT","OR","XOR","DIV"},0),0,1,2,3,4,5,6,7,8,9,10,11,12,13,14,15,16,17,18) -> 3 | F5: =IF(C5="AX",0,IF(C5="BX",1,IF(C5="CX",2,IF(C5="DX",3,VALUE(C5))))) -> 1 | G5: =IF(OR(D5="AX",D5="BX",D5="CX",D5="DX"), IF(OR(E5=12,E5=14,E5=16,E5=17,E5=18), IF(D5="AX",128+0,IF(D5="BX",128+1,IF(D5="CX",128+2,128+3))), IF(D5="AX",0,IF(D5="BX",1,IF(D5="CX",2,3))) ), VALUE(D5)) -> 0 | H5: =IF(E5=0,"NOP",IF(E5=1,"LDI "&CHOOSE(F5+1,"AX","BX","CX","DX")&","&G5,IF(E5=2,"LDR "&CHOOSE(F5+1,"AX","BX","CX","DX")&",["&G5&"]",IF(E5=3,"STR ["&F5&"],AX",IF(E5=4,"MOV "&CHOOSE(F5+1,"AX","BX","CX","DX")&","&CHOOSE(G5+1,"AX","BX","CX","DX"),IF(E5=5,"ADDI "&CHOOSE(F5+1,"AX","BX","CX","DX")&","&G5,IF(E5=6,"ADDR "&CHOOSE(F5+1,"AX","BX","CX","DX")&","&CHOOSE(G5+1,"AX","BX","CX","DX"),IF(E5=7,"SUBI "&CHOOSE(F5+1,"AX","BX","CX","DX")&","&G5,IF(E5=8,"SUBR "&CHOOSE(F5+1,"AX","BX","CX","DX")&","&CHOOSE(G5+1,"AX","BX","CX","DX"),IF(E5=9,"JMP "&F5,IF(E5=10,"JZ "&F5,IF(E5=11,"JNZ "&F5,IF(E5=12,"MUL "&CHOOSE(F5+1,"AX","BX","CX","DX")&","&IF(G5>=128,CHOOSE(G5-128+1,"AX","BX","CX","DX"),G5),IF(E5=13,"LOOP "&F5,IF(E5=14,"AND "&CHOOSE(F5+1,"AX","BX","CX","DX")&","&IF(G5>=128,CHOOSE(G5-128+1,"AX","BX","CX","DX"),G5),IF(E5=15,"HLT",IF(E5=16,"OR "&CHOOSE(F5+1,"AX","BX","CX","DX")&","&IF(G5>=128,CHOOSE(G5-128+1,"AX","BX","CX","DX"),G5),IF(E5=17,"XOR "&CHOOSE(F5+1,"AX","BX","CX","DX")&","&IF(G5>=128,CHOOSE(G5-128+1,"AX","BX","CX","DX"),G5),IF(E5=18,"DIV AX,"&IF(G5>=128,CHOOSE(G5-128+1,"AX","BX","CX","DX"),G5),"???"))))))))))))))))))) -> STR [1],AX | K5: SUBI | L5: DX | M5: 0 | P5: LOOP | Q5: 2 | U5: SUBI | V5: DX | W5: 0
A6: 4 | B6: HLT | E6: =CHOOSE(MATCH(B6,{"NOP","LDI","LDR","STR","MOV","ADDI","ADDR","SUBI","SUBR","JMP","JZ","JNZ","MUL","LOOP","AND","HLT","OR","XOR","DIV"},0),0,1,2,3,4,5,6,7,8,9,10,11,12,13,14,15,16,17,18) -> 15 | F6: =IF(C6="AX",0,IF(C6="BX",1,IF(C6="CX",2,IF(C6="DX",3,VALUE(C6))))) -> 0 | G6: =IF(OR(D6="AX",D6="BX",D6="CX",D6="DX"), IF(OR(E6=12,E6=14,E6=16,E6=17,E6=18), IF(D6="AX",128+0,IF(D6="BX",128+1,IF(D6="CX",128+2,128+3))), IF(D6="AX",0,IF(D6="BX",1,IF(D6="CX",2,3))) ), VALUE(D6)) -> 0 | H6: =IF(E6=0,"NOP",IF(E6=1,"LDI "&CHOOSE(F6+1,"AX","BX","CX","DX")&","&G6,IF(E6=2,"LDR "&CHOOSE(F6+1,"AX","BX","CX","DX")&",["&G6&"]",IF(E6=3,"STR ["&F6&"],AX",IF(E6=4,"MOV "&CHOOSE(F6+1,"AX","BX","CX","DX")&","&CHOOSE(G6+1,"AX","BX","CX","DX"),IF(E6=5,"ADDI "&CHOOSE(F6+1,"AX","BX","CX","DX")&","&G6,IF(E6=6,"ADDR "&CHOOSE(F6+1,"AX","BX","CX","DX")&","&CHOOSE(G6+1,"AX","BX","CX","DX"),IF(E6=7,"SUBI "&CHOOSE(F6+1,"AX","BX","CX","DX")&","&G6,IF(E6=8,"SUBR "&CHOOSE(F6+1,"AX","BX","CX","DX")&","&CHOOSE(G6+1,"AX","BX","CX","DX"),IF(E6=9,"JMP "&F6,IF(E6=10,"JZ "&F6,IF(E6=11,"JNZ "&F6,IF(E6=12,"MUL "&CHOOSE(F6+1,"AX","BX","CX","DX")&","&IF(G6>=128,CHOOSE(G6-128+1,"AX","BX","CX","DX"),G6),IF(E6=13,"LOOP "&F6,IF(E6=14,"AND "&CHOOSE(F6+1,"AX","BX","CX","DX")&","&IF(G6>=128,CHOOSE(G6-128+1,"AX","BX","CX","DX"),G6),IF(E6=15,"HLT",IF(E6=16,"OR "&CHOOSE(F6+1,"AX","BX","CX","DX")&","&IF(G6>=128,CHOOSE(G6-128+1,"AX","BX","CX","DX"),G6),IF(E6=17,"XOR "&CHOOSE(F6+1,"AX","BX","CX","DX")&","&IF(G6>=128,CHOOSE(G6-128+1,"AX","BX","CX","DX"),G6),IF(E6=18,"DIV AX,"&IF(G6>=128,CHOOSE(G6-128+1,"AX","BX","CX","DX"),G6),"???"))))))))))))))))))) -> HLT | K6: JZ | L6: 8 | P6: STR | Q6: 11 | U6: JZ | V6: 10
A7: 5 | E7: =CHOOSE(MATCH(B7,{"NOP","LDI","LDR","STR","MOV","ADDI","ADDR","SUBI","SUBR","JMP","JZ","JNZ","MUL","LOOP","AND","HLT","OR","XOR","DIV"},0),0,1,2,3,4,5,6,7,8,9,10,11,12,13,14,15,16,17,18) -> #N/A | F7: =IF(C7="AX",0,IF(C7="BX",1,IF(C7="CX",2,IF(C7="DX",3,VALUE(C7))))) -> 0 | G7: =IF(OR(D7="AX",D7="BX",D7="CX",D7="DX"), IF(OR(E7=12,E7=14,E7=16,E7=17,E7=18), IF(D7="AX",128+0,IF(D7="BX",128+1,IF(D7="CX",128+2,128+3))), IF(D7="AX",0,IF(D7="BX",1,IF(D7="CX",2,3))) ), VALUE(D7)) -> 0 | H7: =IF(E7=0,"NOP",IF(E7=1,"LDI "&CHOOSE(F7+1,"AX","BX","CX","DX")&","&G7,IF(E7=2,"LDR "&CHOOSE(F7+1,"AX","BX","CX","DX")&",["&G7&"]",IF(E7=3,"STR ["&F7&"],AX",IF(E7=4,"MOV "&CHOOSE(F7+1,"AX","BX","CX","DX")&","&CHOOSE(G7+1,"AX","BX","CX","DX"),IF(E7=5,"ADDI "&CHOOSE(F7+1,"AX","BX","CX","DX")&","&G7,IF(E7=6,"ADDR "&CHOOSE(F7+1,"AX","BX","CX","DX")&","&CHOOSE(G7+1,"AX","BX","CX","DX"),IF(E7=7,"SUBI "&CHOOSE(F7+1,"AX","BX","CX","DX")&","&G7,IF(E7=8,"SUBR "&CHOOSE(F7+1,"AX","BX","CX","DX")&","&CHOOSE(G7+1,"AX","BX","CX","DX"),IF(E7=9,"JMP "&F7,IF(E7=10,"JZ "&F7,IF(E7=11,"JNZ "&F7,IF(E7=12,"MUL "&CHOOSE(F7+1,"AX","BX","CX","DX")&","&IF(G7>=128,CHOOSE(G7-128+1,"AX","BX","CX","DX"),G7),IF(E7=13,"LOOP "&F7,IF(E7=14,"AND "&CHOOSE(F7+1,"AX","BX","CX","DX")&","&IF(G7>=128,CHOOSE(G7-128+1,"AX","BX","CX","DX"),G7),IF(E7=15,"HLT",IF(E7=16,"OR "&CHOOSE(F7+1,"AX","BX","CX","DX")&","&IF(G7>=128,CHOOSE(G7-128+1,"AX","BX","CX","DX"),G7),IF(E7=17,"XOR "&CHOOSE(F7+1,"AX","BX","CX","DX")&","&IF(G7>=128,CHOOSE(G7-128+1,"AX","BX","CX","DX"),G7),IF(E7=18,"DIV AX,"&IF(G7>=128,CHOOSE(G7-128+1,"AX","BX","CX","DX"),G7),"???"))))))))))))))))))) -> #N/A | K7: MUL | L7: AX | M7: CX | P7: HLT | U7: DIV | V7: CX
A8: 6 | E8: =CHOOSE(MATCH(B8,{"NOP","LDI","LDR","STR","MOV","ADDI","ADDR","SUBI","SUBR","JMP","JZ","JNZ","MUL","LOOP","AND","HLT","OR","XOR","DIV"},0),0,1,2,3,4,5,6,7,8,9,10,11,12,13,14,15,16,17,18) -> #N/A | F8: =IF(C8="AX",0,IF(C8="BX",1,IF(C8="CX",2,IF(C8="DX",3,VALUE(C8))))) -> 0 | G8: =IF(OR(D8="AX",D8="BX",D8="CX",D8="DX"), IF(OR(E8=12,E8=14,E8=16,E8=17,E8=18), IF(D8="AX",128+0,IF(D8="BX",128+1,IF(D8="CX",128+2,128+3))), IF(D8="AX",0,IF(D8="BX",1,IF(D8="CX",2,3))) ), VALUE(D8)) -> 0 | H8: =IF(E8=0,"NOP",IF(E8=1,"LDI "&CHOOSE(F8+1,"AX","BX","CX","DX")&","&G8,IF(E8=2,"LDR "&CHOOSE(F8+1,"AX","BX","CX","DX")&",["&G8&"]",IF(E8=3,"STR ["&F8&"],AX",IF(E8=4,"MOV "&CHOOSE(F8+1,"AX","BX","CX","DX")&","&CHOOSE(G8+1,"AX","BX","CX","DX"),IF(E8=5,"ADDI "&CHOOSE(F8+1,"AX","BX","CX","DX")&","&G8,IF(E8=6,"ADDR "&CHOOSE(F8+1,"AX","BX","CX","DX")&","&CHOOSE(G8+1,"AX","BX","CX","DX"),IF(E8=7,"SUBI "&CHOOSE(F8+1,"AX","BX","CX","DX")&","&G8,IF(E8=8,"SUBR "&CHOOSE(F8+1,"AX","BX","CX","DX")&","&CHOOSE(G8+1,"AX","BX","CX","DX"),IF(E8=9,"JMP "&F8,IF(E8=10,"JZ "&F8,IF(E8=11,"JNZ "&F8,IF(E8=12,"MUL "&CHOOSE(F8+1,"AX","BX","CX","DX")&","&IF(G8>=128,CHOOSE(G8-128+1,"AX","BX","CX","DX"),G8),IF(E8=13,"LOOP "&F8,IF(E8=14,"AND "&CHOOSE(F8+1,"AX","BX","CX","DX")&","&IF(G8>=128,CHOOSE(G8-128+1,"AX","BX","CX","DX"),G8),IF(E8=15,"HLT",IF(E8=16,"OR "&CHOOSE(F8+1,"AX","BX","CX","DX")&","&IF(G8>=128,CHOOSE(G8-128+1,"AX","BX","CX","DX"),G8),IF(E8=17,"XOR "&CHOOSE(F8+1,"AX","BX","CX","DX")&","&IF(G8>=128,CHOOSE(G8-128+1,"AX","BX","CX","DX"),G8),IF(E8=18,"DIV AX,"&IF(G8>=128,CHOOSE(G8-128+1,"AX","BX","CX","DX"),G8),"???"))))))))))))))))))) -> #N/A | K8: SUBI | L8: CX | M8: 1 | U8: MOV | V8: AX | W8: CX
A9: 7 | E9: =CHOOSE(MATCH(B9,{"NOP","LDI","LDR","STR","MOV","ADDI","ADDR","SUBI","SUBR","JMP","JZ","JNZ","MUL","LOOP","AND","HLT","OR","XOR","DIV"},0),0,1,2,3,4,5,6,7,8,9,10,11,12,13,14,15,16,17,18) -> #N/A | F9: =IF(C9="AX",0,IF(C9="BX",1,IF(C9="CX",2,IF(C9="DX",3,VALUE(C9))))) -> 0 | G9: =IF(OR(D9="AX",D9="BX",D9="CX",D9="DX"), IF(OR(E9=12,E9=14,E9=16,E9=17,E9=18), IF(D9="AX",128+0,IF(D9="BX",128+1,IF(D9="CX",128+2,128+3))), IF(D9="AX",0,IF(D9="BX",1,IF(D9="CX",2,3))) ), VALUE(D9)) -> 0 | H9: =IF(E9=0,"NOP",IF(E9=1,"LDI "&CHOOSE(F9+1,"AX","BX","CX","DX")&","&G9,IF(E9=2,"LDR "&CHOOSE(F9+1,"AX","BX","CX","DX")&",["&G9&"]",IF(E9=3,"STR ["&F9&"],AX",IF(E9=4,"MOV "&CHOOSE(F9+1,"AX","BX","CX","DX")&","&CHOOSE(G9+1,"AX","BX","CX","DX"),IF(E9=5,"ADDI "&CHOOSE(F9+1,"AX","BX","CX","DX")&","&G9,IF(E9=6,"ADDR "&CHOOSE(F9+1,"AX","BX","CX","DX")&","&CHOOSE(G9+1,"AX","BX","CX","DX"),IF(E9=7,"SUBI "&CHOOSE(F9+1,"AX","BX","CX","DX")&","&G9,IF(E9=8,"SUBR "&CHOOSE(F9+1,"AX","BX","CX","DX")&","&CHOOSE(G9+1,"AX","BX","CX","DX"),IF(E9=9,"JMP "&F9,IF(E9=10,"JZ "&F9,IF(E9=11,"JNZ "&F9,IF(E9=12,"MUL "&CHOOSE(F9+1,"AX","BX","CX","DX")&","&IF(G9>=128,CHOOSE(G9-128+1,"AX","BX","CX","DX"),G9),IF(E9=13,"LOOP "&F9,IF(E9=14,"AND "&CHOOSE(F9+1,"AX","BX","CX","DX")&","&IF(G9>=128,CHOOSE(G9-128+1,"AX","BX","CX","DX"),G9),IF(E9=15,"HLT",IF(E9=16,"OR "&CHOOSE(F9+1,"AX","BX","CX","DX")&","&IF(G9>=128,CHOOSE(G9-128+1,"AX","BX","CX","DX"),G9),IF(E9=17,"XOR "&CHOOSE(F9+1,"AX","BX","CX","DX")&","&IF(G9>=128,CHOOSE(G9-128+1,"AX","BX","CX","DX"),G9),IF(E9=18,"DIV AX,"&IF(G9>=128,CHOOSE(G9-128+1,"AX","BX","CX","DX"),G9),"???"))))))))))))))))))) -> #N/A | K9: JNZ | L9: 5 | U9: MOV | V9: CX | W9: DX
A10: 8 | E10: =CHOOSE(MATCH(B10,{"NOP","LDI","LDR","STR","MOV","ADDI","ADDR","SUBI","SUBR","JMP","JZ","JNZ","MUL","LOOP","AND","HLT","OR","XOR","DIV"},0),0,1,2,3,4,5,6,7,8,9,10,11,12,13,14,15,16,17,18) -> #N/A | F10: =IF(C10="AX",0,IF(C10="BX",1,IF(C10="CX",2,IF(C10="DX",3,VALUE(C10))))) -> 0 | G10: =IF(OR(D10="AX",D10="BX",D10="CX",D10="DX"), IF(OR(E10=12,E10=14,E10=16,E10=17,E10=18), IF(D10="AX",128+0,IF(D10="BX",128+1,IF(D10="CX",128+2,128+3))), IF(D10="AX",0,IF(D10="BX",1,IF(D10="CX",2,3))) ), VALUE(D10)) -> 0 | H10: =IF(E10=0,"NOP",IF(E10=1,"LDI "&CHOOSE(F10+1,"AX","BX","CX","DX")&","&G10,IF(E10=2,"LDR "&CHOOSE(F10+1,"AX","BX","CX","DX")&",["&G10&"]",IF(E10=3,"STR ["&F10&"],AX",IF(E10=4,"MOV "&CHOOSE(F10+1,"AX","BX","CX","DX")&","&CHOOSE(G10+1,"AX","BX","CX","DX"),IF(E10=5,"ADDI "&CHOOSE(F10+1,"AX","BX","CX","DX")&","&G10,IF(E10=6,"ADDR "&CHOOSE(F10+1,"AX","BX","CX","DX")&","&CHOOSE(G10+1,"AX","BX","CX","DX"),IF(E10=7,"SUBI "&CHOOSE(F10+1,"AX","BX","CX","DX")&","&G10,IF(E10=8,"SUBR "&CHOOSE(F10+1,"AX","BX","CX","DX")&","&CHOOSE(G10+1,"AX","BX","CX","DX"),IF(E10=9,"JMP "&F10,IF(E10=10,"JZ "&F10,IF(E10=11,"JNZ "&F10,IF(E10=12,"MUL "&CHOOSE(F10+1,"AX","BX","CX","DX")&","&IF(G10>=128,CHOOSE(G10-128+1,"AX","BX","CX","DX"),G10),IF(E10=13,"LOOP "&F10,IF(E10=14,"AND "&CHOOSE(F10+1,"AX","BX","CX","DX")&","&IF(G10>=128,CHOOSE(G10-128+1,"AX","BX","CX","DX"),G10),IF(E10=15,"HLT",IF(E10=16,"OR "&CHOOSE(F10+1,"AX","BX","CX","DX")&","&IF(G10>=128,CHOOSE(G10-128+1,"AX","BX","CX","DX"),G10),IF(E10=17,"XOR "&CHOOSE(F10+1,"AX","BX","CX","DX")&","&IF(G10>=128,CHOOSE(G10-128+1,"AX","BX","CX","DX"),G10),IF(E10=18,"DIV AX,"&IF(G10>=128,CHOOSE(G10-128+1,"AX","BX","CX","DX"),G10),"???"))))))))))))))))))) -> #N/A | K10: STR | L10: 11 | U10: JMP | V10: 2
A11: 9 | E11: =CHOOSE(MATCH(B11,{"NOP","LDI","LDR","STR","MOV","ADDI","ADDR","SUBI","SUBR","JMP","JZ","JNZ","MUL","LOOP","AND","HLT","OR","XOR","DIV"},0),0,1,2,3,4,5,6,7,8,9,10,11,12,13,14,15,16,17,18) -> #N/A | F11: =IF(C11="AX",0,IF(C11="BX",1,IF(C11="CX",2,IF(C11="DX",3,VALUE(C11))))) -> 0 | G11: =IF(OR(D11="AX",D11="BX",D11="CX",D11="DX"), IF(OR(E11=12,E11=14,E11=16,E11=17,E11=18), IF(D11="AX",128+0,IF(D11="BX",128+1,IF(D11="CX",128+2,128+3))), IF(D11="AX",0,IF(D11="BX",1,IF(D11="CX",2,3))) ), VALUE(D11)) -> 0 | H11: =IF(E11=0,"NOP",IF(E11=1,"LDI "&CHOOSE(F11+1,"AX","BX","CX","DX")&","&G11,IF(E11=2,"LDR "&CHOOSE(F11+1,"AX","BX","CX","DX")&",["&G11&"]",IF(E11=3,"STR ["&F11&"],AX",IF(E11=4,"MOV "&CHOOSE(F11+1,"AX","BX","CX","DX")&","&CHOOSE(G11+1,"AX","BX","CX","DX"),IF(E11=5,"ADDI "&CHOOSE(F11+1,"AX","BX","CX","DX")&","&G11,IF(E11=6,"ADDR "&CHOOSE(F11+1,"AX","BX","CX","DX")&","&CHOOSE(G11+1,"AX","BX","CX","DX"),IF(E11=7,"SUBI "&CHOOSE(F11+1,"AX","BX","CX","DX")&","&G11,IF(E11=8,"SUBR "&CHOOSE(F11+1,"AX","BX","CX","DX")&","&CHOOSE(G11+1,"AX","BX","CX","DX"),IF(E11=9,"JMP "&F11,IF(E11=10,"JZ "&F11,IF(E11=11,"JNZ "&F11,IF(E11=12,"MUL "&CHOOSE(F11+1,"AX","BX","CX","DX")&","&IF(G11>=128,CHOOSE(G11-128+1,"AX","BX","CX","DX"),G11),IF(E11=13,"LOOP "&F11,IF(E11=14,"AND "&CHOOSE(F11+1,"AX","BX","CX","DX")&","&IF(G11>=128,CHOOSE(G11-128+1,"AX","BX","CX","DX"),G11),IF(E11=15,"HLT",IF(E11=16,"OR "&CHOOSE(F11+1,"AX","BX","CX","DX")&","&IF(G11>=128,CHOOSE(G11-128+1,"AX","BX","CX","DX"),G11),IF(E11=17,"XOR "&CHOOSE(F11+1,"AX","BX","CX","DX")&","&IF(G11>=128,CHOOSE(G11-128+1,"AX","BX","CX","DX"),G11),IF(E11=18,"DIV AX,"&IF(G11>=128,CHOOSE(G11-128+1,"AX","BX","CX","DX"),G11),"???"))))))))))))))))))) -> #N/A | K11: HLT | U11: STR | V11: 3
A12: 10 | E12: =CHOOSE(MATCH(B12,{"NOP","LDI","LDR","STR","MOV","ADDI","ADDR","SUBI","SUBR","JMP","JZ","JNZ","MUL","LOOP","AND","HLT","OR","XOR","DIV"},0),0,1,2,3,4,5,6,7,8,9,10,11,12,13,14,15,16,17,18) -> #N/A | F12: =IF(C12="AX",0,IF(C12="BX",1,IF(C12="CX",2,IF(C12="DX",3,VALUE(C12))))) -> 0 | G12: =IF(OR(D12="AX",D12="BX",D12="CX",D12="DX"), IF(OR(E12=12,E12=14,E12=16,E12=17,E12=18), IF(D12="AX",128+0,IF(D12="BX",128+1,IF(D12="CX",128+2,128+3))), IF(D12="AX",0,IF(D12="BX",1,IF(D12="CX",2,3))) ), VALUE(D12)) -> 0 | H12: =IF(E12=0,"NOP",IF(E12=1,"LDI "&CHOOSE(F12+1,"AX","BX","CX","DX")&","&G12,IF(E12=2,"LDR "&CHOOSE(F12+1,"AX","BX","CX","DX")&",["&G12&"]",IF(E12=3,"STR ["&F12&"],AX",IF(E12=4,"MOV "&CHOOSE(F12+1,"AX","BX","CX","DX")&","&CHOOSE(G12+1,"AX","BX","CX","DX"),IF(E12=5,"ADDI "&CHOOSE(F12+1,"AX","BX","CX","DX")&","&G12,IF(E12=6,"ADDR "&CHOOSE(F12+1,"AX","BX","CX","DX")&","&CHOOSE(G12+1,"AX","BX","CX","DX"),IF(E12=7,"SUBI "&CHOOSE(F12+1,"AX","BX","CX","DX")&","&G12,IF(E12=8,"SUBR "&CHOOSE(F12+1,"AX","BX","CX","DX")&","&CHOOSE(G12+1,"AX","BX","CX","DX"),IF(E12=9,"JMP "&F12,IF(E12=10,"JZ "&F12,IF(E12=11,"JNZ "&F12,IF(E12=12,"MUL "&CHOOSE(F12+1,"AX","BX","CX","DX")&","&IF(G12>=128,CHOOSE(G12-128+1,"AX","BX","CX","DX"),G12),IF(E12=13,"LOOP "&F12,IF(E12=14,"AND "&CHOOSE(F12+1,"AX","BX","CX","DX")&","&IF(G12>=128,CHOOSE(G12-128+1,"AX","BX","CX","DX"),G12),IF(E12=15,"HLT",IF(E12=16,"OR "&CHOOSE(F12+1,"AX","BX","CX","DX")&","&IF(G12>=128,CHOOSE(G12-128+1,"AX","BX","CX","DX"),G12),IF(E12=17,"XOR "&CHOOSE(F12+1,"AX","BX","CX","DX")&","&IF(G12>=128,CHOOSE(G12-128+1,"AX","BX","CX","DX"),G12),IF(E12=18,"DIV AX,"&IF(G12>=128,CHOOSE(G12-128+1,"AX","BX","CX","DX"),G12),"???"))))))))))))))))))) -> #N/A | U12: HLT
A13: 11 | E13: =CHOOSE(MATCH(B13,{"NOP","LDI","LDR","STR","MOV","ADDI","ADDR","SUBI","SUBR","JMP","JZ","JNZ","MUL","LOOP","AND","HLT","OR","XOR","DIV"},0),0,1,2,3,4,5,6,7,8,9,10,11,12,13,14,15,16,17,18) -> #N/A | F13: =IF(C13="AX",0,IF(C13="BX",1,IF(C13="CX",2,IF(C13="DX",3,VALUE(C13))))) -> 0 | G13: =IF(OR(D13="AX",D13="BX",D13="CX",D13="DX"), IF(OR(E13=12,E13=14,E13=16,E13=17,E13=18), IF(D13="AX",128+0,IF(D13="BX",128+1,IF(D13="CX",128+2,128+3))), IF(D13="AX",0,IF(D13="BX",1,IF(D13="CX",2,3))) ), VALUE(D13)) -> 0 | H13: =IF(E13=0,"NOP",IF(E13=1,"LDI "&CHOOSE(F13+1,"AX","BX","CX","DX")&","&G13,IF(E13=2,"LDR "&CHOOSE(F13+1,"AX","BX","CX","DX")&",["&G13&"]",IF(E13=3,"STR ["&F13&"],AX",IF(E13=4,"MOV "&CHOOSE(F13+1,"AX","BX","CX","DX")&","&CHOOSE(G13+1,"AX","BX","CX","DX"),IF(E13=5,"ADDI "&CHOOSE(F13+1,"AX","BX","CX","DX")&","&G13,IF(E13=6,"ADDR "&CHOOSE(F13+1,"AX","BX","CX","DX")&","&CHOOSE(G13+1,"AX","BX","CX","DX"),IF(E13=7,"SUBI "&CHOOSE(F13+1,"AX","BX","CX","DX")&","&G13,IF(E13=8,"SUBR "&CHOOSE(F13+1,"AX","BX","CX","DX")&","&CHOOSE(G13+1,"AX","BX","CX","DX"),IF(E13=9,"JMP "&F13,IF(E13=10,"JZ "&F13,IF(E13=11,"JNZ "&F13,IF(E13=12,"MUL "&CHOOSE(F13+1,"AX","BX","CX","DX")&","&IF(G13>=128,CHOOSE(G13-128+1,"AX","BX","CX","DX"),G13),IF(E13=13,"LOOP "&F13,IF(E13=14,"AND "&CHOOSE(F13+1,"AX","BX","CX","DX")&","&IF(G13>=128,CHOOSE(G13-128+1,"AX","BX","CX","DX"),G13),IF(E13=15,"HLT",IF(E13=16,"OR "&CHOOSE(F13+1,"AX","BX","CX","DX")&","&IF(G13>=128,CHOOSE(G13-128+1,"AX","BX","CX","DX"),G13),IF(E13=17,"XOR "&CHOOSE(F13+1,"AX","BX","CX","DX")&","&IF(G13>=128,CHOOSE(G13-128+1,"AX","BX","CX","DX"),G13),IF(E13=18,"DIV AX,"&IF(G13>=128,CHOOSE(G13-128+1,"AX","BX","CX","DX"),G13),"???"))))))))))))))))))) -> #N/A
A14: 12 | E14: =CHOOSE(MATCH(B14,{"NOP","LDI","LDR","STR","MOV","ADDI","ADDR","SUBI","SUBR","JMP","JZ","JNZ","MUL","LOOP","AND","HLT","OR","XOR","DIV"},0),0,1,2,3,4,5,6,7,8,9,10,11,12,13,14,15,16,17,18) -> #N/A | F14: =IF(C14="AX",0,IF(C14="BX",1,IF(C14="CX",2,IF(C14="DX",3,VALUE(C14))))) -> 0 | G14: =IF(OR(D14="AX",D14="BX",D14="CX",D14="DX"), IF(OR(E14=12,E14=14,E14=16,E14=17,E14=18), IF(D14="AX",128+0,IF(D14="BX",128+1,IF(D14="CX",128+2,128+3))), IF(D14="AX",0,IF(D14="BX",1,IF(D14="CX",2,3))) ), VALUE(D14)) -> 0 | H14: =IF(E14=0,"NOP",IF(E14=1,"LDI "&CHOOSE(F14+1,"AX","BX","CX","DX")&","&G14,IF(E14=2,"LDR "&CHOOSE(F14+1,"AX","BX","CX","DX")&",["&G14&"]",IF(E14=3,"STR ["&F14&"],AX",IF(E14=4,"MOV "&CHOOSE(F14+1,"AX","BX","CX","DX")&","&CHOOSE(G14+1,"AX","BX","CX","DX"),IF(E14=5,"ADDI "&CHOOSE(F14+1,"AX","BX","CX","DX")&","&G14,IF(E14=6,"ADDR "&CHOOSE(F14+1,"AX","BX","CX","DX")&","&CHOOSE(G14+1,"AX","BX","CX","DX"),IF(E14=7,"SUBI "&CHOOSE(F14+1,"AX","BX","CX","DX")&","&G14,IF(E14=8,"SUBR "&CHOOSE(F14+1,"AX","BX","CX","DX")&","&CHOOSE(G14+1,"AX","BX","CX","DX"),IF(E14=9,"JMP "&F14,IF(E14=10,"JZ "&F14,IF(E14=11,"JNZ "&F14,IF(E14=12,"MUL "&CHOOSE(F14+1,"AX","BX","CX","DX")&","&IF(G14>=128,CHOOSE(G14-128+1,"AX","BX","CX","DX"),G14),IF(E14=13,"LOOP "&F14,IF(E14=14,"AND "&CHOOSE(F14+1,"AX","BX","CX","DX")&","&IF(G14>=128,CHOOSE(G14-128+1,"AX","BX","CX","DX"),G14),IF(E14=15,"HLT",IF(E14=16,"OR "&CHOOSE(F14+1,"AX","BX","CX","DX")&","&IF(G14>=128,CHOOSE(G14-128+1,"AX","BX","CX","DX"),G14),IF(E14=17,"XOR "&CHOOSE(F14+1,"AX","BX","CX","DX")&","&IF(G14>=128,CHOOSE(G14-128+1,"AX","BX","CX","DX"),G14),IF(E14=18,"DIV AX,"&IF(G14>=128,CHOOSE(G14-128+1,"AX","BX","CX","DX"),G14),"???"))))))))))))))))))) -> #N/A
A15: 13 | E15: =CHOOSE(MATCH(B15,{"NOP","LDI","LDR","STR","MOV","ADDI","ADDR","SUBI","SUBR","JMP","JZ","JNZ","MUL","LOOP","AND","HLT","OR","XOR","DIV"},0),0,1,2,3,4,5,6,7,8,9,10,11,12,13,14,15,16,17,18) -> #N/A | F15: =IF(C15="AX",0,IF(C15="BX",1,IF(C15="CX",2,IF(C15="DX",3,VALUE(C15))))) -> 0 | G15: =IF(OR(D15="AX",D15="BX",D15="CX",D15="DX"), IF(OR(E15=12,E15=14,E15=16,E15=17,E15=18), IF(D15="AX",128+0,IF(D15="BX",128+1,IF(D15="CX",128+2,128+3))), IF(D15="AX",0,IF(D15="BX",1,IF(D15="CX",2,3))) ), VALUE(D15)) -> 0 | H15: =IF(E15=0,"NOP",IF(E15=1,"LDI "&CHOOSE(F15+1,"AX","BX","CX","DX")&","&G15,IF(E15=2,"LDR "&CHOOSE(F15+1,"AX","BX","CX","DX")&",["&G15&"]",IF(E15=3,"STR ["&F15&"],AX",IF(E15=4,"MOV "&CHOOSE(F15+1,"AX","BX","CX","DX")&","&CHOOSE(G15+1,"AX","BX","CX","DX"),IF(E15=5,"ADDI "&CHOOSE(F15+1,"AX","BX","CX","DX")&","&G15,IF(E15=6,"ADDR "&CHOOSE(F15+1,"AX","BX","CX","DX")&","&CHOOSE(G15+1,"AX","BX","CX","DX"),IF(E15=7,"SUBI "&CHOOSE(F15+1,"AX","BX","CX","DX")&","&G15,IF(E15=8,"SUBR "&CHOOSE(F15+1,"AX","BX","CX","DX")&","&CHOOSE(G15+1,"AX","BX","CX","DX"),IF(E15=9,"JMP "&F15,IF(E15=10,"JZ "&F15,IF(E15=11,"JNZ "&F15,IF(E15=12,"MUL "&CHOOSE(F15+1,"AX","BX","CX","DX")&","&IF(G15>=128,CHOOSE(G15-128+1,"AX","BX","CX","DX"),G15),IF(E15=13,"LOOP "&F15,IF(E15=14,"AND "&CHOOSE(F15+1,"AX","BX","CX","DX")&","&IF(G15>=128,CHOOSE(G15-128+1,"AX","BX","CX","DX"),G15),IF(E15=15,"HLT",IF(E15=16,"OR "&CHOOSE(F15+1,"AX","BX","CX","DX")&","&IF(G15>=128,CHOOSE(G15-128+1,"AX","BX","CX","DX"),G15),IF(E15=17,"XOR "&CHOOSE(F15+1,"AX","BX","CX","DX")&","&IF(G15>=128,CHOOSE(G15-128+1,"AX","BX","CX","DX"),G15),IF(E15=18,"DIV AX,"&IF(G15>=128,CHOOSE(G15-128+1,"AX","BX","CX","DX"),G15),"???"))))))))))))))))))) -> #N/A
A16: 14 | E16: =CHOOSE(MATCH(B16,{"NOP","LDI","LDR","STR","MOV","ADDI","ADDR","SUBI","SUBR","JMP","JZ","JNZ","MUL","LOOP","AND","HLT","OR","XOR","DIV"},0),0,1,2,3,4,5,6,7,8,9,10,11,12,13,14,15,16,17,18) -> #N/A | F16: =IF(C16="AX",0,IF(C16="BX",1,IF(C16="CX",2,IF(C16="DX",3,VALUE(C16))))) -> 0 | G16: =IF(OR(D16="AX",D16="BX",D16="CX",D16="DX"), IF(OR(E16=12,E16=14,E16=16,E16=17,E16=18), IF(D16="AX",128+0,IF(D16="BX",128+1,IF(D16="CX",128+2,128+3))), IF(D16="AX",0,IF(D16="BX",1,IF(D16="CX",2,3))) ), VALUE(D16)) -> 0 | H16: =IF(E16=0,"NOP",IF(E16=1,"LDI "&CHOOSE(F16+1,"AX","BX","CX","DX")&","&G16,IF(E16=2,"LDR "&CHOOSE(F16+1,"AX","BX","CX","DX")&",["&G16&"]",IF(E16=3,"STR ["&F16&"],AX",IF(E16=4,"MOV "&CHOOSE(F16+1,"AX","BX","CX","DX")&","&CHOOSE(G16+1,"AX","BX","CX","DX"),IF(E16=5,"ADDI "&CHOOSE(F16+1,"AX","BX","CX","DX")&","&G16,IF(E16=6,"ADDR "&CHOOSE(F16+1,"AX","BX","CX","DX")&","&CHOOSE(G16+1,"AX","BX","CX","DX"),IF(E16=7,"SUBI "&CHOOSE(F16+1,"AX","BX","CX","DX")&","&G16,IF(E16=8,"SUBR "&CHOOSE(F16+1,"AX","BX","CX","DX")&","&CHOOSE(G16+1,"AX","BX","CX","DX"),IF(E16=9,"JMP "&F16,IF(E16=10,"JZ "&F16,IF(E16=11,"JNZ "&F16,IF(E16=12,"MUL "&CHOOSE(F16+1,"AX","BX","CX","DX")&","&IF(G16>=128,CHOOSE(G16-128+1,"AX","BX","CX","DX"),G16),IF(E16=13,"LOOP "&F16,IF(E16=14,"AND "&CHOOSE(F16+1,"AX","BX","CX","DX")&","&IF(G16>=128,CHOOSE(G16-128+1,"AX","BX","CX","DX"),G16),IF(E16=15,"HLT",IF(E16=16,"OR "&CHOOSE(F16+1,"AX","BX","CX","DX")&","&IF(G16>=128,CHOOSE(G16-128+1,"AX","BX","CX","DX"),G16),IF(E16=17,"XOR "&CHOOSE(F16+1,"AX","BX","CX","DX")&","&IF(G16>=128,CHOOSE(G16-128+1,"AX","BX","CX","DX"),G16),IF(E16=18,"DIV AX,"&IF(G16>=128,CHOOSE(G16-128+1,"AX","BX","CX","DX"),G16),"???"))))))))))))))))))) -> #N/A
A17: 15 | E17: =CHOOSE(MATCH(B17,{"NOP","LDI","LDR","STR","MOV","ADDI","ADDR","SUBI","SUBR","JMP","JZ","JNZ","MUL","LOOP","AND","HLT","OR","XOR","DIV"},0),0,1,2,3,4,5,6,7,8,9,10,11,12,13,14,15,16,17,18) -> #N/A | F17: =IF(C17="AX",0,IF(C17="BX",1,IF(C17="CX",2,IF(C17="DX",3,VALUE(C17))))) -> 0 | G17: =IF(OR(D17="AX",D17="BX",D17="CX",D17="DX"), IF(OR(E17=12,E17=14,E17=16,E17=17,E17=18), IF(D17="AX",128+0,IF(D17="BX",128+1,IF(D17="CX",128+2,128+3))), IF(D17="AX",0,IF(D17="BX",1,IF(D17="CX",2,3))) ), VALUE(D17)) -> 0 | H17: =IF(E17=0,"NOP",IF(E17=1,"LDI "&CHOOSE(F17+1,"AX","BX","CX","DX")&","&G17,IF(E17=2,"LDR "&CHOOSE(F17+1,"AX","BX","CX","DX")&",["&G17&"]",IF(E17=3,"STR ["&F17&"],AX",IF(E17=4,"MOV "&CHOOSE(F17+1,"AX","BX","CX","DX")&","&CHOOSE(G17+1,"AX","BX","CX","DX"),IF(E17=5,"ADDI "&CHOOSE(F17+1,"AX","BX","CX","DX")&","&G17,IF(E17=6,"ADDR "&CHOOSE(F17+1,"AX","BX","CX","DX")&","&CHOOSE(G17+1,"AX","BX","CX","DX"),IF(E17=7,"SUBI "&CHOOSE(F17+1,"AX","BX","CX","DX")&","&G17,IF(E17=8,"SUBR "&CHOOSE(F17+1,"AX","BX","CX","DX")&","&CHOOSE(G17+1,"AX","BX","CX","DX"),IF(E17=9,"JMP "&F17,IF(E17=10,"JZ "&F17,IF(E17=11,"JNZ "&F17,IF(E17=12,"MUL "&CHOOSE(F17+1,"AX","BX","CX","DX")&","&IF(G17>=128,CHOOSE(G17-128+1,"AX","BX","CX","DX"),G17),IF(E17=13,"LOOP "&F17,IF(E17=14,"AND "&CHOOSE(F17+1,"AX","BX","CX","DX")&","&IF(G17>=128,CHOOSE(G17-128+1,"AX","BX","CX","DX"),G17),IF(E17=15,"HLT",IF(E17=16,"OR "&CHOOSE(F17+1,"AX","BX","CX","DX")&","&IF(G17>=128,CHOOSE(G17-128+1,"AX","BX","CX","DX"),G17),IF(E17=17,"XOR "&CHOOSE(F17+1,"AX","BX","CX","DX")&","&IF(G17>=128,CHOOSE(G17-128+1,"AX","BX","CX","DX"),G17),IF(E17=18,"DIV AX,"&IF(G17>=128,CHOOSE(G17-128+1,"AX","BX","CX","DX"),G17),"???"))))))))))))))))))) -> #N/A
A18: 16 | E18: =CHOOSE(MATCH(B18,{"NOP","LDI","LDR","STR","MOV","ADDI","ADDR","SUBI","SUBR","JMP","JZ","JNZ","MUL","LOOP","AND","HLT","OR","XOR","DIV"},0),0,1,2,3,4,5,6,7,8,9,10,11,12,13,14,15,16,17,18) -> #N/A | F18: =IF(C18="AX",0,IF(C18="BX",1,IF(C18="CX",2,IF(C18="DX",3,VALUE(C18))))) -> 0 | G18: =IF(OR(D18="AX",D18="BX",D18="CX",D18="DX"), IF(OR(E18=12,E18=14,E18=16,E18=17,E18=18), IF(D18="AX",128+0,IF(D18="BX",128+1,IF(D18="CX",128+2,128+3))), IF(D18="AX",0,IF(D18="BX",1,IF(D18="CX",2,3))) ), VALUE(D18)) -> 0 | H18: =IF(E18=0,"NOP",IF(E18=1,"LDI "&CHOOSE(F18+1,"AX","BX","CX","DX")&","&G18,IF(E18=2,"LDR "&CHOOSE(F18+1,"AX","BX","CX","DX")&",["&G18&"]",IF(E18=3,"STR ["&F18&"],AX",IF(E18=4,"MOV "&CHOOSE(F18+1,"AX","BX","CX","DX")&","&CHOOSE(G18+1,"AX","BX","CX","DX"),IF(E18=5,"ADDI "&CHOOSE(F18+1,"AX","BX","CX","DX")&","&G18,IF(E18=6,"ADDR "&CHOOSE(F18+1,"AX","BX","CX","DX")&","&CHOOSE(G18+1,"AX","BX","CX","DX"),IF(E18=7,"SUBI "&CHOOSE(F18+1,"AX","BX","CX","DX")&","&G18,IF(E18=8,"SUBR "&CHOOSE(F18+1,"AX","BX","CX","DX")&","&CHOOSE(G18+1,"AX","BX","CX","DX"),IF(E18=9,"JMP "&F18,IF(E18=10,"JZ "&F18,IF(E18=11,"JNZ "&F18,IF(E18=12,"MUL "&CHOOSE(F18+1,"AX","BX","CX","DX")&","&IF(G18>=128,CHOOSE(G18-128+1,"AX","BX","CX","DX"),G18),IF(E18=13,"LOOP "&F18,IF(E18=14,"AND "&CHOOSE(F18+1,"AX","BX","CX","DX")&","&IF(G18>=128,CHOOSE(G18-128+1,"AX","BX","CX","DX"),G18),IF(E18=15,"HLT",IF(E18=16,"OR "&CHOOSE(F18+1,"AX","BX","CX","DX")&","&IF(G18>=128,CHOOSE(G18-128+1,"AX","BX","CX","DX"),G18),IF(E18=17,"XOR "&CHOOSE(F18+1,"AX","BX","CX","DX")&","&IF(G18>=128,CHOOSE(G18-128+1,"AX","BX","CX","DX"),G18),IF(E18=18,"DIV AX,"&IF(G18>=128,CHOOSE(G18-128+1,"AX","BX","CX","DX"),G18),"???"))))))))))))))))))) -> #N/A
A19: 17 | E19: =CHOOSE(MATCH(B19,{"NOP","LDI","LDR","STR","MOV","ADDI","ADDR","SUBI","SUBR","JMP","JZ","JNZ","MUL","LOOP","AND","HLT","OR","XOR","DIV"},0),0,1,2,3,4,5,6,7,8,9,10,11,12,13,14,15,16,17,18) -> #N/A | F19: =IF(C19="AX",0,IF(C19="BX",1,IF(C19="CX",2,IF(C19="DX",3,VALUE(C19))))) -> 0 | G19: =IF(OR(D19="AX",D19="BX",D19="CX",D19="DX"), IF(OR(E19=12,E19=14,E19=16,E19=17,E19=18), IF(D19="AX",128+0,IF(D19="BX",128+1,IF(D19="CX",128+2,128+3))), IF(D19="AX",0,IF(D19="BX",1,IF(D19="CX",2,3))) ), VALUE(D19)) -> 0 | H19: =IF(E19=0,"NOP",IF(E19=1,"LDI "&CHOOSE(F19+1,"AX","BX","CX","DX")&","&G19,IF(E19=2,"LDR "&CHOOSE(F19+1,"AX","BX","CX","DX")&",["&G19&"]",IF(E19=3,"STR ["&F19&"],AX",IF(E19=4,"MOV "&CHOOSE(F19+1,"AX","BX","CX","DX")&","&CHOOSE(G19+1,"AX","BX","CX","DX"),IF(E19=5,"ADDI "&CHOOSE(F19+1,"AX","BX","CX","DX")&","&G19,IF(E19=6,"ADDR "&CHOOSE(F19+1,"AX","BX","CX","DX")&","&CHOOSE(G19+1,"AX","BX","CX","DX"),IF(E19=7,"SUBI "&CHOOSE(F19+1,"AX","BX","CX","DX")&","&G19,IF(E19=8,"SUBR "&CHOOSE(F19+1,"AX","BX","CX","DX")&","&CHOOSE(G19+1,"AX","BX","CX","DX"),IF(E19=9,"JMP "&F19,IF(E19=10,"JZ "&F19,IF(E19=11,"JNZ "&F19,IF(E19=12,"MUL "&CHOOSE(F19+1,"AX","BX","CX","DX")&","&IF(G19>=128,CHOOSE(G19-128+1,"AX","BX","CX","DX"),G19),IF(E19=13,"LOOP "&F19,IF(E19=14,"AND "&CHOOSE(F19+1,"AX","BX","CX","DX")&","&IF(G19>=128,CHOOSE(G19-128+1,"AX","BX","CX","DX"),G19),IF(E19=15,"HLT",IF(E19=16,"OR "&CHOOSE(F19+1,"AX","BX","CX","DX")&","&IF(G19>=128,CHOOSE(G19-128+1,"AX","BX","CX","DX"),G19),IF(E19=17,"XOR "&CHOOSE(F19+1,"AX","BX","CX","DX")&","&IF(G19>=128,CHOOSE(G19-128+1,"AX","BX","CX","DX"),G19),IF(E19=18,"DIV AX,"&IF(G19>=128,CHOOSE(G19-128+1,"AX","BX","CX","DX"),G19),"???"))))))))))))))))))) -> #N/A
A20: 18 | E20: =CHOOSE(MATCH(B20,{"NOP","LDI","LDR","STR","MOV","ADDI","ADDR","SUBI","SUBR","JMP","JZ","JNZ","MUL","LOOP","AND","HLT","OR","XOR","DIV"},0),0,1,2,3,4,5,6,7,8,9,10,11,12,13,14,15,16,17,18) -> #N/A | F20: =IF(C20="AX",0,IF(C20="BX",1,IF(C20="CX",2,IF(C20="DX",3,VALUE(C20))))) -> 0 | G20: =IF(OR(D20="AX",D20="BX",D20="CX",D20="DX"), IF(OR(E20=12,E20=14,E20=16,E20=17,E20=18), IF(D20="AX",128+0,IF(D20="BX",128+1,IF(D20="CX",128+2,128+3))), IF(D20="AX",0,IF(D20="BX",1,IF(D20="CX",2,3))) ), VALUE(D20)) -> 0 | H20: =IF(E20=0,"NOP",IF(E20=1,"LDI "&CHOOSE(F20+1,"AX","BX","CX","DX")&","&G20,IF(E20=2,"LDR "&CHOOSE(F20+1,"AX","BX","CX","DX")&",["&G20&"]",IF(E20=3,"STR ["&F20&"],AX",IF(E20=4,"MOV "&CHOOSE(F20+1,"AX","BX","CX","DX")&","&CHOOSE(G20+1,"AX","BX","CX","DX"),IF(E20=5,"ADDI "&CHOOSE(F20+1,"AX","BX","CX","DX")&","&G20,IF(E20=6,"ADDR "&CHOOSE(F20+1,"AX","BX","CX","DX")&","&CHOOSE(G20+1,"AX","BX","CX","DX"),IF(E20=7,"SUBI "&CHOOSE(F20+1,"AX","BX","CX","DX")&","&G20,IF(E20=8,"SUBR "&CHOOSE(F20+1,"AX","BX","CX","DX")&","&CHOOSE(G20+1,"AX","BX","CX","DX"),IF(E20=9,"JMP "&F20,IF(E20=10,"JZ "&F20,IF(E20=11,"JNZ "&F20,IF(E20=12,"MUL "&CHOOSE(F20+1,"AX","BX","CX","DX")&","&IF(G20>=128,CHOOSE(G20-128+1,"AX","BX","CX","DX"),G20),IF(E20=13,"LOOP "&F20,IF(E20=14,"AND "&CHOOSE(F20+1,"AX","BX","CX","DX")&","&IF(G20>=128,CHOOSE(G20-128+1,"AX","BX","CX","DX"),G20),IF(E20=15,"HLT",IF(E20=16,"OR "&CHOOSE(F20+1,"AX","BX","CX","DX")&","&IF(G20>=128,CHOOSE(G20-128+1,"AX","BX","CX","DX"),G20),IF(E20=17,"XOR "&CHOOSE(F20+1,"AX","BX","CX","DX")&","&IF(G20>=128,CHOOSE(G20-128+1,"AX","BX","CX","DX"),G20),IF(E20=18,"DIV AX,"&IF(G20>=128,CHOOSE(G20-128+1,"AX","BX","CX","DX"),G20),"???"))))))))))))))))))) -> #N/A
A21: 19 | E21: =CHOOSE(MATCH(B21,{"NOP","LDI","LDR","STR","MOV","ADDI","ADDR","SUBI","SUBR","JMP","JZ","JNZ","MUL","LOOP","AND","HLT","OR","XOR","DIV"},0),0,1,2,3,4,5,6,7,8,9,10,11,12,13,14,15,16,17,18) -> #N/A | F21: =IF(C21="AX",0,IF(C21="BX",1,IF(C21="CX",2,IF(C21="DX",3,VALUE(C21))))) -> 0 | G21: =IF(OR(D21="AX",D21="BX",D21="CX",D21="DX"), IF(OR(E21=12,E21=14,E21=16,E21=17,E21=18), IF(D21="AX",128+0,IF(D21="BX",128+1,IF(D21="CX",128+2,128+3))), IF(D21="AX",0,IF(D21="BX",1,IF(D21="CX",2,3))) ), VALUE(D21)) -> 0 | H21: =IF(E21=0,"NOP",IF(E21=1,"LDI "&CHOOSE(F21+1,"AX","BX","CX","DX")&","&G21,IF(E21=2,"LDR "&CHOOSE(F21+1,"AX","BX","CX","DX")&",["&G21&"]",IF(E21=3,"STR ["&F21&"],AX",IF(E21=4,"MOV "&CHOOSE(F21+1,"AX","BX","CX","DX")&","&CHOOSE(G21+1,"AX","BX","CX","DX"),IF(E21=5,"ADDI "&CHOOSE(F21+1,"AX","BX","CX","DX")&","&G21,IF(E21=6,"ADDR "&CHOOSE(F21+1,"AX","BX","CX","DX")&","&CHOOSE(G21+1,"AX","BX","CX","DX"),IF(E21=7,"SUBI "&CHOOSE(F21+1,"AX","BX","CX","DX")&","&G21,IF(E21=8,"SUBR "&CHOOSE(F21+1,"AX","BX","CX","DX")&","&CHOOSE(G21+1,"AX","BX","CX","DX"),IF(E21=9,"JMP "&F21,IF(E21=10,"JZ "&F21,IF(E21=11,"JNZ "&F21,IF(E21=12,"MUL "&CHOOSE(F21+1,"AX","BX","CX","DX")&","&IF(G21>=128,CHOOSE(G21-128+1,"AX","BX","CX","DX"),G21),IF(E21=13,"LOOP "&F21,IF(E21=14,"AND "&CHOOSE(F21+1,"AX","BX","CX","DX")&","&IF(G21>=128,CHOOSE(G21-128+1,"AX","BX","CX","DX"),G21),IF(E21=15,"HLT",IF(E21=16,"OR "&CHOOSE(F21+1,"AX","BX","CX","DX")&","&IF(G21>=128,CHOOSE(G21-128+1,"AX","BX","CX","DX"),G21),IF(E21=17,"XOR "&CHOOSE(F21+1,"AX","BX","CX","DX")&","&IF(G21>=128,CHOOSE(G21-128+1,"AX","BX","CX","DX"),G21),IF(E21=18,"DIV AX,"&IF(G21>=128,CHOOSE(G21-128+1,"AX","BX","CX","DX"),G21),"???"))))))))))))))))))) -> #N/A
A22: 20 | E22: =CHOOSE(MATCH(B22,{"NOP","LDI","LDR","STR","MOV","ADDI","ADDR","SUBI","SUBR","JMP","JZ","JNZ","MUL","LOOP","AND","HLT","OR","XOR","DIV"},0),0,1,2,3,4,5,6,7,8,9,10,11,12,13,14,15,16,17,18) -> #N/A | F22: =IF(C22="AX",0,IF(C22="BX",1,IF(C22="CX",2,IF(C22="DX",3,VALUE(C22))))) -> 0 | G22: =IF(OR(D22="AX",D22="BX",D22="CX",D22="DX"), IF(OR(E22=12,E22=14,E22=16,E22=17,E22=18), IF(D22="AX",128+0,IF(D22="BX",128+1,IF(D22="CX",128+2,128+3))), IF(D22="AX",0,IF(D22="BX",1,IF(D22="CX",2,3))) ), VALUE(D22)) -> 0 | H22: =IF(E22=0,"NOP",IF(E22=1,"LDI "&CHOOSE(F22+1,"AX","BX","CX","DX")&","&G22,IF(E22=2,"LDR "&CHOOSE(F22+1,"AX","BX","CX","DX")&",["&G22&"]",IF(E22=3,"STR ["&F22&"],AX",IF(E22=4,"MOV "&CHOOSE(F22+1,"AX","BX","CX","DX")&","&CHOOSE(G22+1,"AX","BX","CX","DX"),IF(E22=5,"ADDI "&CHOOSE(F22+1,"AX","BX","CX","DX")&","&G22,IF(E22=6,"ADDR "&CHOOSE(F22+1,"AX","BX","CX","DX")&","&CHOOSE(G22+1,"AX","BX","CX","DX"),IF(E22=7,"SUBI "&CHOOSE(F22+1,"AX","BX","CX","DX")&","&G22,IF(E22=8,"SUBR "&CHOOSE(F22+1,"AX","BX","CX","DX")&","&CHOOSE(G22+1,"AX","BX","CX","DX"),IF(E22=9,"JMP "&F22,IF(E22=10,"JZ "&F22,IF(E22=11,"JNZ "&F22,IF(E22=12,"MUL "&CHOOSE(F22+1,"AX","BX","CX","DX")&","&IF(G22>=128,CHOOSE(G22-128+1,"AX","BX","CX","DX"),G22),IF(E22=13,"LOOP "&F22,IF(E22=14,"AND "&CHOOSE(F22+1,"AX","BX","CX","DX")&","&IF(G22>=128,CHOOSE(G22-128+1,"AX","BX","CX","DX"),G22),IF(E22=15,"HLT",IF(E22=16,"OR "&CHOOSE(F22+1,"AX","BX","CX","DX")&","&IF(G22>=128,CHOOSE(G22-128+1,"AX","BX","CX","DX"),G22),IF(E22=17,"XOR "&CHOOSE(F22+1,"AX","BX","CX","DX")&","&IF(G22>=128,CHOOSE(G22-128+1,"AX","BX","CX","DX"),G22),IF(E22=18,"DIV AX,"&IF(G22>=128,CHOOSE(G22-128+1,"AX","BX","CX","DX"),G22),"???"))))))))))))))))))) -> #N/A
A23: 21 | E23: =CHOOSE(MATCH(B23,{"NOP","LDI","LDR","STR","MOV","ADDI","ADDR","SUBI","SUBR","JMP","JZ","JNZ","MUL","LOOP","AND","HLT","OR","XOR","DIV"},0),0,1,2,3,4,5,6,7,8,9,10,11,12,13,14,15,16,17,18) -> #N/A | F23: =IF(C23="AX",0,IF(C23="BX",1,IF(C23="CX",2,IF(C23="DX",3,VALUE(C23))))) -> 0 | G23: =IF(OR(D23="AX",D23="BX",D23="CX",D23="DX"), IF(OR(E23=12,E23=14,E23=16,E23=17,E23=18), IF(D23="AX",128+0,IF(D23="BX",128+1,IF(D23="CX",128+2,128+3))), IF(D23="AX",0,IF(D23="BX",1,IF(D23="CX",2,3))) ), VALUE(D23)) -> 0 | H23: =IF(E23=0,"NOP",IF(E23=1,"LDI "&CHOOSE(F23+1,"AX","BX","CX","DX")&","&G23,IF(E23=2,"LDR "&CHOOSE(F23+1,"AX","BX","CX","DX")&",["&G23&"]",IF(E23=3,"STR ["&F23&"],AX",IF(E23=4,"MOV "&CHOOSE(F23+1,"AX","BX","CX","DX")&","&CHOOSE(G23+1,"AX","BX","CX","DX"),IF(E23=5,"ADDI "&CHOOSE(F23+1,"AX","BX","CX","DX")&","&G23,IF(E23=6,"ADDR "&CHOOSE(F23+1,"AX","BX","CX","DX")&","&CHOOSE(G23+1,"AX","BX","CX","DX"),IF(E23=7,"SUBI "&CHOOSE(F23+1,"AX","BX","CX","DX")&","&G23,IF(E23=8,"SUBR "&CHOOSE(F23+1,"AX","BX","CX","DX")&","&CHOOSE(G23+1,"AX","BX","CX","DX"),IF(E23=9,"JMP "&F23,IF(E23=10,"JZ "&F23,IF(E23=11,"JNZ "&F23,IF(E23=12,"MUL "&CHOOSE(F23+1,"AX","BX","CX","DX")&","&IF(G23>=128,CHOOSE(G23-128+1,"AX","BX","CX","DX"),G23),IF(E23=13,"LOOP "&F23,IF(E23=14,"AND "&CHOOSE(F23+1,"AX","BX","CX","DX")&","&IF(G23>=128,CHOOSE(G23-128+1,"AX","BX","CX","DX"),G23),IF(E23=15,"HLT",IF(E23=16,"OR "&CHOOSE(F23+1,"AX","BX","CX","DX")&","&IF(G23>=128,CHOOSE(G23-128+1,"AX","BX","CX","DX"),G23),IF(E23=17,"XOR "&CHOOSE(F23+1,"AX","BX","CX","DX")&","&IF(G23>=128,CHOOSE(G23-128+1,"AX","BX","CX","DX"),G23),IF(E23=18,"DIV AX,"&IF(G23>=128,CHOOSE(G23-128+1,"AX","BX","CX","DX"),G23),"???"))))))))))))))))))) -> #N/A
A24: 22 | E24: =CHOOSE(MATCH(B24,{"NOP","LDI","LDR","STR","MOV","ADDI","ADDR","SUBI","SUBR","JMP","JZ","JNZ","MUL","LOOP","AND","HLT","OR","XOR","DIV"},0),0,1,2,3,4,5,6,7,8,9,10,11,12,13,14,15,16,17,18) -> #N/A | F24: =IF(C24="AX",0,IF(C24="BX",1,IF(C24="CX",2,IF(C24="DX",3,VALUE(C24))))) -> 0 | G24: =IF(OR(D24="AX",D24="BX",D24="CX",D24="DX"), IF(OR(E24=12,E24=14,E24=16,E24=17,E24=18), IF(D24="AX",128+0,IF(D24="BX",128+1,IF(D24="CX",128+2,128+3))), IF(D24="AX",0,IF(D24="BX",1,IF(D24="CX",2,3))) ), VALUE(D24)) -> 0 | H24: =IF(E24=0,"NOP",IF(E24=1,"LDI "&CHOOSE(F24+1,"AX","BX","CX","DX")&","&G24,IF(E24=2,"LDR "&CHOOSE(F24+1,"AX","BX","CX","DX")&",["&G24&"]",IF(E24=3,"STR ["&F24&"],AX",IF(E24=4,"MOV "&CHOOSE(F24+1,"AX","BX","CX","DX")&","&CHOOSE(G24+1,"AX","BX","CX","DX"),IF(E24=5,"ADDI "&CHOOSE(F24+1,"AX","BX","CX","DX")&","&G24,IF(E24=6,"ADDR "&CHOOSE(F24+1,"AX","BX","CX","DX")&","&CHOOSE(G24+1,"AX","BX","CX","DX"),IF(E24=7,"SUBI "&CHOOSE(F24+1,"AX","BX","CX","DX")&","&G24,IF(E24=8,"SUBR "&CHOOSE(F24+1,"AX","BX","CX","DX")&","&CHOOSE(G24+1,"AX","BX","CX","DX"),IF(E24=9,"JMP "&F24,IF(E24=10,"JZ "&F24,IF(E24=11,"JNZ "&F24,IF(E24=12,"MUL "&CHOOSE(F24+1,"AX","BX","CX","DX")&","&IF(G24>=128,CHOOSE(G24-128+1,"AX","BX","CX","DX"),G24),IF(E24=13,"LOOP "&F24,IF(E24=14,"AND "&CHOOSE(F24+1,"AX","BX","CX","DX")&","&IF(G24>=128,CHOOSE(G24-128+1,"AX","BX","CX","DX"),G24),IF(E24=15,"HLT",IF(E24=16,"OR "&CHOOSE(F24+1,"AX","BX","CX","DX")&","&IF(G24>=128,CHOOSE(G24-128+1,"AX","BX","CX","DX"),G24),IF(E24=17,"XOR "&CHOOSE(F24+1,"AX","BX","CX","DX")&","&IF(G24>=128,CHOOSE(G24-128+1,"AX","BX","CX","DX"),G24),IF(E24=18,"DIV AX,"&IF(G24>=128,CHOOSE(G24-128+1,"AX","BX","CX","DX"),G24),"???"))))))))))))))))))) -> #N/A
... A257: 255 | E257: =CHOOSE(MATCH(B257,{"NOP","LDI","LDR","STR","MOV","ADDI","ADDR","SUBI","SUBR","JMP","JZ","JNZ","MUL","LOOP","AND","HLT","OR","XOR","DIV"},0),0,1,2,3,4,5,6,7,8,9,10,11,12,13,14,15,16,17,18) -> #N/A | F257: =IF(C257="AX",0,IF(C257="BX",1,IF(C257="CX",2,IF(C257="DX",3,VALUE(C257))))) -> 0 | G257: =IF(OR(D257="AX",D257="BX",D257="CX",D257="DX"), IF(OR(E257=12,E257=14,E257=16,E257=17,E257=18), IF(D257="AX",128+0,IF(D257="BX",128+1,IF(D257="CX",128+2,128+3))), IF(D257="AX",0,IF(D257="BX",1,IF(D257="CX",2,3))) ), VALUE(D257)) -> 0 | H257: =IF(E257=0,"NOP",IF(E257=1,"LDI "&CHOOSE(F257+1,"AX","BX","CX","DX")&","&G257,IF(E257=2,"LDR "&CHOOSE(F257+1,"AX","BX","CX","DX")&",["&G257&"]",IF(E257=3,"STR ["&F257&"],AX",IF(E257=4,"MOV "&CHOOSE(F257+1,"AX","BX","CX","DX")&","&CHOOSE(G257+1,"AX","BX","CX","DX"),IF(E257=5,"ADDI "&CHOOSE(F257+1,"AX","BX","CX","DX")&","&G257,IF(E257=6,"ADDR "&CHOOSE(F257+1,"AX","BX","CX","DX")&","&CHOOSE(G257+1,"AX","BX","CX","DX"),IF(E257=7,"SUBI "&CHOOSE(F257+1,"AX","BX","CX","DX")&","&G257,IF(E257=8,"SUBR "&CHOOSE(F257+1,"AX","BX","CX","DX")&","&CHOOSE(G257+1,"AX","BX","CX","DX"),IF(E257=9,"JMP "&F257,IF(E257=10,"JZ "&F257,IF(E257=11,"JNZ "&F257,IF(E257=12,"MUL "&CHOOSE(F257+1,"AX","BX","CX","DX")&","&IF(G257>=128,CHOOSE(G257-128+1,"AX","BX","CX","DX"),G257),IF(E257=13,"LOOP "&F257,IF(E257=14,"AND "&CHOOSE(F257+1,"AX","BX","CX","DX")&","&IF(G257>=128,CHOOSE(G257-128+1,"AX","BX","CX","DX"),G257),IF(E257=15,"HLT",IF(E257=16,"OR "&CHOOSE(F257+1,"AX","BX","CX","DX")&","&IF(G257>=128,CHOOSE(G257-128+1,"AX","BX","CX","DX"),G257),IF(E257=17,"XOR "&CHOOSE(F257+1,"AX","BX","CX","DX")&","&IF(G257>=128,CHOOSE(G257-128+1,"AX","BX","CX","DX"),G257),IF(E257=18,"DIV AX,"&IF(G257>=128,CHOOSE(G257-128+1,"AX","BX","CX","DX"),G257),"???"))))))))))))))))))) -> #N/A

Sheet RAM
A1: ADDR | B1: VALUE (initial)
A2: 0 | B2: 0
A3: 1 | B3: 36
A4: 2 | B4: 15
A5: 3 | B5: 0
A6: 4 | B6: 0
A7: 5 | B7: 0
A8: 6 | B8: 0
A9: 7 | B9: 5
A10: 8 | B10: 0
A11: 9 | B11: 0
A12: 10 | B12: 3
A13: 11 | B13: 0
... A17: 15 | B17: 0

Sheet CPU
A1: Cycle | B1: PC | C1: AX | D1: BX | E1: CX | F1: DX | G1: ZF | H1: CF | I1: SF | J1: Opcode | K1: Arg1 | L1: Arg2 | M1: Halted | N1: RAM0 | O1: RAM1 | P1: RAM2 | Q1: RAM3 | R1: RAM4 | S1: RAM5 | T1: RAM6 | U1: RAM7 | V1: RAM8 | W1: RAM9 | X1: RAM10 | Y1: RAM11 | Z1: RAM12 | AA1: RAM13 | AB1: RAM14 | AC1: RAM15
A2: 0 | B2: 0 | C2: 0 | D2: 0 | E2: 0 | F2: 0 | G2: 0 | H2: 0 | I2: 0 | J2: {=INDEX(PROGRAM!$E$2:$E$257, B2+1)} -> 1 | K2: {=INDEX(PROGRAM!$F$2:$F$257, B2+1)} -> 0 | L2: {=INDEX(PROGRAM!$G$2:$G$257, B2+1)} -> 5 | M2: 0 | N2: =RAM!B2 -> 0 | O2: =RAM!B3 -> 36 | P2: =RAM!B4 -> 15 | Q2: =RAM!B5 -> 0 | R2: =RAM!B6 -> 0 | S2: =RAM!B7 -> 0 | T2: =RAM!B8 -> 0 | U2: =RAM!B9 -> 5 | V2: =RAM!B10 -> 0 | W2: =RAM!B11 -> 0 | X2: =RAM!B12 -> 3 | Y2: =RAM!B13 -> 0 | Z2: =RAM!B14 -> 0 | AA2: =RAM!B15 -> 0 | AB2: =RAM!B16 -> 0 | AC2: =RAM!B17 -> 0
A3: =A2+1 -> 1 | B3: =IF(M2=1,B2,IF(J2=15,B2,IF(J2=9,K2,IF(J2=10,IF(G2=1,K2,B2+1),IF(J2=11,IF(G2=0,K2,B2+1),IF(J2=13,IF(MOD(E2-1,256)<>0,K2,B2+1),B2+1)))))) -> 1 | C3: {=IF(M2=1,C2,IF(J2=15,C2,IF(J2=1,IF(K2=0,L2,C2),IF(J2=2,IF(K2=0,INDEX(N2:AC2,1,L2+1),C2),IF(J2=4,IF(K2=0,CHOOSE(L2+1,C2,D2,E2,F2),C2),IF(J2=5,IF(K2=0,MOD(C2+L2,256),C2),IF(J2=6,IF(K2=0,MOD(C2+CHOOSE(L2+1,C2,D2,E2,F2),256),C2),IF(J2=7,IF(K2=0,MOD(C2-L2,256),C2),IF(J2=8,IF(K2=0,MOD(C2-CHOOSE(L2+1,C2,D2,E2,F2),256),C2),IF(J2=12,IF(K2=0,MOD(C2*(IF(L2>=128,CHOOSE(L2-128+1,C2,D2,E2,F2),L2)),256),C2),IF(J2=14,IF(K2=0,_xlfn.BITAND(C2,(IF(L2>=128,CHOOSE(L2-128+1,C2,D2,E2,F2),L2))),C2),IF(J2=16,IF(K2=0,_xlfn.BITOR(C2,(IF(L2>=128,CHOOSE(L2-128+1,C2,D2,E2,F2),L2))),C2),IF(J2=17,IF(K2=0,_xlfn.BITXOR(C2,(IF(L2>=128,CHOOSE(L2-128+1,C2,D2,E2,F2),L2))),C2),IF(J2=18,IF(0=1,QUOTIENT(C2,(IF(L2>=128,CHOOSE(L2-128+1,C2,D2,E2,F2),L2))),IF(0=3,MOD(C2,(IF(L2>=128,CHOOSE(L2-128+1,C2,D2,E2,F2),L2))),C2)),IF(J2=13,C2,C2)))))))))))))))} -> 5 | D3: {=IF(M2=1,D2,IF(J2=15,D2,IF(J2=1,IF(K2=1,L2,D2),IF(J2=2,IF(K2=1,INDEX(N2:AC2,1,L2+1),D2),IF(J2=4,IF(K2=1,CHOOSE(L2+1,C2,D2,E2,F2),D2),IF(J2=5,IF(K2=1,MOD(D2+L2,256),D2),IF(J2=6,IF(K2=1,MOD(D2+CHOOSE(L2+1,C2,D2,E2,F2),256),D2),IF(J2=7,IF(K2=1,MOD(D2-L2,256),D2),IF(J2=8,IF(K2=1,MOD(D2-CHOOSE(L2+1,C2,D2,E2,F2),256),D2),IF(J2=12,IF(K2=1,MOD(D2*(IF(L2>=128,CHOOSE(L2-128+1,C2,D2,E2,F2),L2)),256),D2),IF(J2=14,IF(K2=1,_xlfn.BITAND(D2,(IF(L2>=128,CHOOSE(L2-128+1,C2,D2,E2,F2),L2))),D2),IF(J2=16,IF(K2=1,_xlfn.BITOR(D2,(IF(L2>=128,CHOOSE(L2-128+1,C2,D2,E2,F2),L2))),D2),IF(J2=17,IF(K2=1,_xlfn.BITXOR(D2,(IF(L2>=128,CHOOSE(L2-128+1,C2,D2,E2,F2),L2))),D2),IF(J2=18,IF(1=1,QUOTIENT(C2,(IF(L2>=128,CHOOSE(L2-128+1,C2,D2,E2,F2),L2))),IF(1=3,MOD(C2,(IF(L2>=128,CHOOSE(L2-128+1,C2,D2,E2,F2),L2))),D2)),IF(J2=13,D2,D2)))))))))))))))} -> 0 | E3: {=IF(M2=1,E2,IF(J2=15,E2,IF(J2=1,IF(K2=2,L2,E2),IF(J2=2,IF(K2=2,INDEX(N2:AC2,1,L2+1),E2),IF(J2=4,IF(K2=2,CHOOSE(L2+1,C2,D2,E2,F2),E2),IF(J2=5,IF(K2=2,MOD(E2+L2,256),E2),IF(J2=6,IF(K2=2,MOD(E2+CHOOSE(L2+1,C2,D2,E2,F2),256),E2),IF(J2=7,IF(K2=2,MOD(E2-L2,256),E2),IF(J2=8,IF(K2=2,MOD(E2-CHOOSE(L2+1,C2,D2,E2,F2),256),E2),IF(J2=12,IF(K2=2,MOD(E2*(IF(L2>=128,CHOOSE(L2-128+1,C2,D2,E2,F2),L2)),256),E2),IF(J2=14,IF(K2=2,_xlfn.BITAND(E2,(IF(L2>=128,CHOOSE(L2-128+1,C2,D2,E2,F2),L2))),E2),IF(J2=16,IF(K2=2,_xlfn.BITOR(E2,(IF(L2>=128,CHOOSE(L2-128+1,C2,D2,E2,F2),L2))),E2),IF(J2=17,IF(K2=2,_xlfn.BITXOR(E2,(IF(L2>=128,CHOOSE(L2-128+1,C2,D2,E2,F2),L2))),E2),IF(J2=18,IF(2=1,QUOTIENT(C2,(IF(L2>=128,CHOOSE(L2-128+1,C2,D2,E2,F2),L2))),IF(2=3,MOD(C2,(IF(L2>=128,CHOOSE(L2-128+1,C2,D2,E2,F2),L2))),E2)),IF(J2=13,MOD(E2-1,256),E2)))))))))))))))} -> 0 | F3: {=IF(M2=1,F2,IF(J2=15,F2,IF(J2=1,IF(K2=3,L2,F2),IF(J2=2,IF(K2=3,INDEX(N2:AC2,1,L2+1),F2),IF(J2=4,IF(K2=3,CHOOSE(L2+1,C2,D2,E2,F2),F2),IF(J2=5,IF(K2=3,MOD(F2+L2,256),F2),IF(J2=6,IF(K2=3,MOD(F2+CHOOSE(L2+1,C2,D2,E2,F2),256),F2),IF(J2=7,IF(K2=3,MOD(F2-L2,256),F2),IF(J2=8,IF(K2=3,MOD(F2-CHOOSE(L2+1,C2,D2,E2,F2),256),F2),IF(J2=12,IF(K2=3,MOD(F2*(IF(L2>=128,CHOOSE(L2-128+1,C2,D2,E2,F2),L2)),256),F2),IF(J2=14,IF(K2=3,_xlfn.BITAND(F2,(IF(L2>=128,CHOOSE(L2-128+1,C2,D2,E2,F2),L2))),F2),IF(J2=16,IF(K2=3,_xlfn.BITOR(F2,(IF(L2>=128,CHOOSE(L2-128+1,C2,D2,E2,F2),L2))),F2),IF(J2=17,IF(K2=3,_xlfn.BITXOR(F2,(IF(L2>=128,CHOOSE(L2-128+1,C2,D2,E2,F2),L2))),F2),IF(J2=18,IF(3=1,QUOTIENT(C2,(IF(L2>=128,CHOOSE(L2-128+1,C2,D2,E2,F2),L2))),IF(3=3,MOD(C2,(IF(L2>=128,CHOOSE(L2-128+1,C2,D2,E2,F2),L2))),F2)),IF(J2=13,F2,F2)))))))))))))))} -> 0 | G3: =IF(M2=1,G2,IF(OR(J2=5,J2=6,J2=7,J2=8),IF(IF(J2=5,MOD(CHOOSE(K2+1,C2,D2,E2,F2)+L2,256),IF(J2=6,MOD(CHOOSE(K2+1,C2,D2,E2,F2)+CHOOSE(L2+1,C2,D2,E2,F2),256),IF(J2=7,MOD(CHOOSE(K2+1,C2,D2,E2,F2)-L2,256),MOD(CHOOSE(K2+1,C2,D2,E2,F2)-CHOOSE(L2+1,C2,D2,E2,F2),256))))=0,1,0),G2)) -> 0 | H3: =IF(M2=1,H2,IF(J2=5,IF(CHOOSE(K2+1,C2,D2,E2,F2)+L2>255,1,0),IF(J2=6,IF(CHOOSE(K2+1,C2,D2,E2,F2)+CHOOSE(L2+1,C2,D2,E2,F2)>255,1,0),IF(J2=7,IF(CHOOSE(K2+1,C2,D2,E2,F2)<L2,1,0),IF(J2=8,IF(CHOOSE(K2+1,C2,D2,E2,F2)<CHOOSE(L2+1,C2,D2,E2,F2),1,0),H2))))) -> 0 | I3: =IF(M2=1,I2,IF(OR(J2=5,J2=6,J2=7,J2=8),IF(IF(J2=5,MOD(CHOOSE(K2+1,C2,D2,E2,F2)+L2,256),IF(J2=6,MOD(CHOOSE(K2+1,C2,D2,E2,F2)+CHOOSE(L2+1,C2,D2,E2,F2),256),IF(J2=7,MOD(CHOOSE(K2+1,C2,D2,E2,F2)-L2,256),MOD(CHOOSE(K2+1,C2,D2,E2,F2)-CHOOSE(L2+1,C2,D2,E2,F2),256))))>=128,1,0),I2)) -> 0 | J3: {=INDEX(PROGRAM!$E$2:$E$257, B3+1)} -> 2 | K3: {=INDEX(PROGRAM!$F$2:$F$257, B3+1)} -> 1 | L3: {=INDEX(PROGRAM!$G$2:$G$257, B3+1)} -> 7 | M3: =IF(M2=1,1,IF(J2=15,1,0)) -> 0 | N3: =IF(M2=1,N2,IF(J2=3,IF(K2=0,C2,N2),N2)) -> 0 | O3: =IF(M2=1,O2,IF(J2=3,IF(K2=1,C2,O2),O2)) -> 36 | P3: =IF(M2=1,P2,IF(J2=3,IF(K2=2,C2,P2),P2)) -> 15 | Q3: =IF(M2=1,Q2,IF(J2=3,IF(K2=3,C2,Q2),Q2)) -> 0 | R3: =IF(M2=1,R2,IF(J2=3,IF(K2=4,C2,R2),R2)) -> 0 | S3: =IF(M2=1,S2,IF(J2=3,IF(K2=5,C2,S2),S2)) -> 0 | T3: =IF(M2=1,T2,IF(J2=3,IF(K2=6,C2,T2),T2)) -> 0 | U3: =IF(M2=1,U2,IF(J2=3,IF(K2=7,C2,U2),U2)) -> 5 | V3: =IF(M2=1,V2,IF(J2=3,IF(K2=8,C2,V2),V2)) -> 0 | W3: =IF(M2=1,W2,IF(J2=3,IF(K2=9,C2,W2),W2)) -> 0 | X3: =IF(M2=1,X2,IF(J2=3,IF(K2=10,C2,X2),X2)) -> 3 | Y3: =IF(M2=1,Y2,IF(J2=3,IF(K2=11,C2,Y2),Y2)) -> 0 | Z3: =IF(M2=1,Z2,IF(J2=3,IF(K2=12,C2,Z2),Z2)) -> 0 | AA3: =IF(M2=1,AA2,IF(J2=3,IF(K2=13,C2,AA2),AA2)) -> 0 | AB3: =IF(M2=1,AB2,IF(J2=3,IF(K2=14,C2,AB2),AB2)) -> 0 | AC3: =IF(M2=1,AC2,IF(J2=3,IF(K2=15,C2,AC2),AC2)) -> 0
A4: =A3+1 -> 2 | B4: =IF(M3=1,B3,IF(J3=15,B3,IF(J3=9,K3,IF(J3=10,IF(G3=1,K3,B3+1),IF(J3=11,IF(G3=0,K3,B3+1),IF(J3=13,IF(MOD(E3-1,256)<>0,K3,B3+1),B3+1)))))) -> 2 | C4: {=IF(M3=1,C3,IF(J3=15,C3,IF(J3=1,IF(K3=0,L3,C3),IF(J3=2,IF(K3=0,INDEX(N3:AC3,1,L3+1),C3),IF(J3=4,IF(K3=0,CHOOSE(L3+1,C3,D3,E3,F3),C3),IF(J3=5,IF(K3=0,MOD(C3+L3,256),C3),IF(J3=6,IF(K3=0,MOD(C3+CHOOSE(L3+1,C3,D3,E3,F3),256),C3),IF(J3=7,IF(K3=0,MOD(C3-L3,256),C3),IF(J3=8,IF(K3=0,MOD(C3-CHOOSE(L3+1,C3,D3,E3,F3),256),C3),IF(J3=12,IF(K3=0,MOD(C3*(IF(L3>=128,CHOOSE(L3-128+1,C3,D3,E3,F3),L3)),256),C3),IF(J3=14,IF(K3=0,_xlfn.BITAND(C3,(IF(L3>=128,CHOOSE(L3-128+1,C3,D3,E3,F3),L3))),C3),IF(J3=16,IF(K3=0,_xlfn.BITOR(C3,(IF(L3>=128,CHOOSE(L3-128+1,C3,D3,E3,F3),L3))),C3),IF(J3=17,IF(K3=0,_xlfn.BITXOR(C3,(IF(L3>=128,CHOOSE(L3-128+1,C3,D3,E3,F3),L3))),C3),IF(J3=18,IF(0=1,QUOTIENT(C3,(IF(L3>=128,CHOOSE(L3-128+1,C3,D3,E3,F3),L3))),IF(0=3,MOD(C3,(IF(L3>=128,CHOOSE(L3-128+1,C3,D3,E3,F3),L3))),C3)),IF(J3=13,C3,C3)))))))))))))))} -> 5 | D4: {=IF(M3=1,D3,IF(J3=15,D3,IF(J3=1,IF(K3=1,L3,D3),IF(J3=2,IF(K3=1,INDEX(N3:AC3,1,L3+1),D3),IF(J3=4,IF(K3=1,CHOOSE(L3+1,C3,D3,E3,F3),D3),IF(J3=5,IF(K3=1,MOD(D3+L3,256),D3),IF(J3=6,IF(K3=1,MOD(D3+CHOOSE(L3+1,C3,D3,E3,F3),256),D3),IF(J3=7,IF(K3=1,MOD(D3-L3,256),D3),IF(J3=8,IF(K3=1,MOD(D3-CHOOSE(L3+1,C3,D3,E3,F3),256),D3),IF(J3=12,IF(K3=1,MOD(D3*(IF(L3>=128,CHOOSE(L3-128+1,C3,D3,E3,F3),L3)),256),D3),IF(J3=14,IF(K3=1,_xlfn.BITAND(D3,(IF(L3>=128,CHOOSE(L3-128+1,C3,D3,E3,F3),L3))),D3),IF(J3=16,IF(K3=1,_xlfn.BITOR(D3,(IF(L3>=128,CHOOSE(L3-128+1,C3,D3,E3,F3),L3))),D3),IF(J3=17,IF(K3=1,_xlfn.BITXOR(D3,(IF(L3>=128,CHOOSE(L3-128+1,C3,D3,E3,F3),L3))),D3),IF(J3=18,IF(1=1,QUOTIENT(C3,(IF(L3>=128,CHOOSE(L3-128+1,C3,D3,E3,F3),L3))),IF(1=3,MOD(C3,(IF(L3>=128,CHOOSE(L3-128+1,C3,D3,E3,F3),L3))),D3)),IF(J3=13,D3,D3)))))))))))))))} -> 5 | E4: {=IF(M3=1,E3,IF(J3=15,E3,IF(J3=1,IF(K3=2,L3,E3),IF(J3=2,IF(K3=2,INDEX(N3:AC3,1,L3+1),E3),IF(J3=4,IF(K3=2,CHOOSE(L3+1,C3,D3,E3,F3),E3),IF(J3=5,IF(K3=2,MOD(E3+L3,256),E3),IF(J3=6,IF(K3=2,MOD(E3+CHOOSE(L3+1,C3,D3,E3,F3),256),E3),IF(J3=7,IF(K3=2,MOD(E3-L3,256),E3),IF(J3=8,IF(K3=2,MOD(E3-CHOOSE(L3+1,C3,D3,E3,F3),256),E3),IF(J3=12,IF(K3=2,MOD(E3*(IF(L3>=128,CHOOSE(L3-128+1,C3,D3,E3,F3),L3)),256),E3),IF(J3=14,IF(K3=2,_xlfn.BITAND(E3,(IF(L3>=128,CHOOSE(L3-128+1,C3,D3,E3,F3),L3))),E3),IF(J3=16,IF(K3=2,_xlfn.BITOR(E3,(IF(L3>=128,CHOOSE(L3-128+1,C3,D3,E3,F3),L3))),E3),IF(J3=17,IF(K3=2,_xlfn.BITXOR(E3,(IF(L3>=128,CHOOSE(L3-128+1,C3,D3,E3,F3),L3))),E3),IF(J3=18,IF(2=1,QUOTIENT(C3,(IF(L3>=128,CHOOSE(L3-128+1,C3,D3,E3,F3),L3))),IF(2=3,MOD(C3,(IF(L3>=128,CHOOSE(L3-128+1,C3,D3,E3,F3),L3))),E3)),IF(J3=13,MOD(E3-1,256),E3)))))))))))))))} -> 0 | F4: {=IF(M3=1,F3,IF(J3=15,F3,IF(J3=1,IF(K3=3,L3,F3),IF(J3=2,IF(K3=3,INDEX(N3:AC3,1,L3+1),F3),IF(J3=4,IF(K3=3,CHOOSE(L3+1,C3,D3,E3,F3),F3),IF(J3=5,IF(K3=3,MOD(F3+L3,256),F3),IF(J3=6,IF(K3=3,MOD(F3+CHOOSE(L3+1,C3,D3,E3,F3),256),F3),IF(J3=7,IF(K3=3,MOD(F3-L3,256),F3),IF(J3=8,IF(K3=3,MOD(F3-CHOOSE(L3+1,C3,D3,E3,F3),256),F3),IF(J3=12,IF(K3=3,MOD(F3*(IF(L3>=128,CHOOSE(L3-128+1,C3,D3,E3,F3),L3)),256),F3),IF(J3=14,IF(K3=3,_xlfn.BITAND(F3,(IF(L3>=128,CHOOSE(L3-128+1,C3,D3,E3,F3),L3))),F3),IF(J3=16,IF(K3=3,_xlfn.BITOR(F3,(IF(L3>=128,CHOOSE(L3-128+1,C3,D3,E3,F3),L3))),F3),IF(J3=17,IF(K3=3,_xlfn.BITXOR(F3,(IF(L3>=128,CHOOSE(L3-128+1,C3,D3,E3,F3),L3))),F3),IF(J3=18,IF(3=1,QUOTIENT(C3,(IF(L3>=128,CHOOSE(L3-128+1,C3,D3,E3,F3),L3))),IF(3=3,MOD(C3,(IF(L3>=128,CHOOSE(L3-128+1,C3,D3,E3,F3),L3))),F3)),IF(J3=13,F3,F3)))))))))))))))} -> 0 | G4: =IF(M3=1,G3,IF(OR(J3=5,J3=6,J3=7,J3=8),IF(IF(J3=5,MOD(CHOOSE(K3+1,C3,D3,E3,F3)+L3,256),IF(J3=6,MOD(CHOOSE(K3+1,C3,D3,E3,F3)+CHOOSE(L3+1,C3,D3,E3,F3),256),IF(J3=7,MOD(CHOOSE(K3+1,C3,D3,E3,F3)-L3,256),MOD(CHOOSE(K3+1,C3,D3,E3,F3)-CHOOSE(L3+1,C3,D3,E3,F3),256))))=0,1,0),G3)) -> 0 | H4: =IF(M3=1,H3,IF(J3=5,IF(CHOOSE(K3+1,C3,D3,E3,F3)+L3>255,1,0),IF(J3=6,IF(CHOOSE(K3+1,C3,D3,E3,F3)+CHOOSE(L3+1,C3,D3,E3,F3)>255,1,0),IF(J3=7,IF(CHOOSE(K3+1,C3,D3,E3,F3)<L3,1,0),IF(J3=8,IF(CHOOSE(K3+1,C3,D3,E3,F3)<CHOOSE(L3+1,C3,D3,E3,F3),1,0),H3))))) -> 0 | I4: =IF(M3=1,I3,IF(OR(J3=5,J3=6,J3=7,J3=8),IF(IF(J3=5,MOD(CHOOSE(K3+1,C3,D3,E3,F3)+L3,256),IF(J3=6,MOD(CHOOSE(K3+1,C3,D3,E3,F3)+CHOOSE(L3+1,C3,D3,E3,F3),256),IF(J3=7,MOD(CHOOSE(K3+1,C3,D3,E3,F3)-L3,256),MOD(CHOOSE(K3+1,C3,D3,E3,F3)-CHOOSE(L3+1,C3,D3,E3,F3),256))))>=128,1,0),I3)) -> 0 | J4: {=INDEX(PROGRAM!$E$2:$E$257, B4+1)} -> 6 | K4: {=INDEX(PROGRAM!$F$2:$F$257, B4+1)} -> 0 | L4: {=INDEX(PROGRAM!$G$2:$G$257, B4+1)} -> 1 | M4: =IF(M3=1,1,IF(J3=15,1,0)) -> 0 | N4: =IF(M3=1,N3,IF(J3=3,IF(K3=0,C3,N3),N3)) -> 0 | O4: =IF(M3=1,O3,IF(J3=3,IF(K3=1,C3,O3),O3)) -> 36 | P4: =IF(M3=1,P3,IF(J3=3,IF(K3=2,C3,P3),P3)) -> 15 | Q4: =IF(M3=1,Q3,IF(J3=3,IF(K3=3,C3,Q3),Q3)) -> 0 | R4: =IF(M3=1,R3,IF(J3=3,IF(K3=4,C3,R3),R3)) -> 0 | S4: =IF(M3=1,S3,IF(J3=3,IF(K3=5,C3,S3),S3)) -> 0 | T4: =IF(M3=1,T3,IF(J3=3,IF(K3=6,C3,T3),T3)) -> 0 | U4: =IF(M3=1,U3,IF(J3=3,IF(K3=7,C3,U3),U3)) -> 5 | V4: =IF(M3=1,V3,IF(J3=3,IF(K3=8,C3,V3),V3)) -> 0 | W4: =IF(M3=1,W3,IF(J3=3,IF(K3=9,C3,W3),W3)) -> 0 | X4: =IF(M3=1,X3,IF(J3=3,IF(K3=10,C3,X3),X3)) -> 3 | Y4: =IF(M3=1,Y3,IF(J3=3,IF(K3=11,C3,Y3),Y3)) -> 0 | Z4: =IF(M3=1,Z3,IF(J3=3,IF(K3=12,C3,Z3),Z3)) -> 0 | AA4: =IF(M3=1,AA3,IF(J3=3,IF(K3=13,C3,AA3),AA3)) -> 0 | AB4: =IF(M3=1,AB3,IF(J3=3,IF(K3=14,C3,AB3),AB3)) -> 0 | AC4: =IF(M3=1,AC3,IF(J3=3,IF(K3=15,C3,AC3),AC3)) -> 0
A5: =A4+1 -> 3 | B5: =IF(M4=1,B4,IF(J4=15,B4,IF(J4=9,K4,IF(J4=10,IF(G4=1,K4,B4+1),IF(J4=11,IF(G4=0,K4,B4+1),IF(J4=13,IF(MOD(E4-1,256)<>0,K4,B4+1),B4+1)))))) -> 3 | C5: {=IF(M4=1,C4,IF(J4=15,C4,IF(J4=1,IF(K4=0,L4,C4),IF(J4=2,IF(K4=0,INDEX(N4:AC4,1,L4+1),C4),IF(J4=4,IF(K4=0,CHOOSE(L4+1,C4,D4,E4,F4),C4),IF(J4=5,IF(K4=0,MOD(C4+L4,256),C4),IF(J4=6,IF(K4=0,MOD(C4+CHOOSE(L4+1,C4,D4,E4,F4),256),C4),IF(J4=7,IF(K4=0,MOD(C4-L4,256),C4),IF(J4=8,IF(K4=0,MOD(C4-CHOOSE(L4+1,C4,D4,E4,F4),256),C4),IF(J4=12,IF(K4=0,MOD(C4*(IF(L4>=128,CHOOSE(L4-128+1,C4,D4,E4,F4),L4)),256),C4),IF(J4=14,IF(K4=0,_xlfn.BITAND(C4,(IF(L4>=128,CHOOSE(L4-128+1,C4,D4,E4,F4),L4))),C4),IF(J4=16,IF(K4=0,_xlfn.BITOR(C4,(IF(L4>=128,CHOOSE(L4-128+1,C4,D4,E4,F4),L4))),C4),IF(J4=17,IF(K4=0,_xlfn.BITXOR(C4,(IF(L4>=128,CHOOSE(L4-128+1,C4,D4,E4,F4),L4))),C4),IF(J4=18,IF(0=1,QUOTIENT(C4,(IF(L4>=128,CHOOSE(L4-128+1,C4,D4,E4,F4),L4))),IF(0=3,MOD(C4,(IF(L4>=128,CHOOSE(L4-128+1,C4,D4,E4,F4),L4))),C4)),IF(J4=13,C4,C4)))))))))))))))} -> 10 | D5: {=IF(M4=1,D4,IF(J4=15,D4,IF(J4=1,IF(K4=1,L4,D4),IF(J4=2,IF(K4=1,INDEX(N4:AC4,1,L4+1),D4),IF(J4=4,IF(K4=1,CHOOSE(L4+1,C4,D4,E4,F4),D4),IF(J4=5,IF(K4=1,MOD(D4+L4,256),D4),IF(J4=6,IF(K4=1,MOD(D4+CHOOSE(L4+1,C4,D4,E4,F4),256),D4),IF(J4=7,IF(K4=1,MOD(D4-L4,256),D4),IF(J4=8,IF(K4=1,MOD(D4-CHOOSE(L4+1,C4,D4,E4,F4),256),D4),IF(J4=12,IF(K4=1,MOD(D4*(IF(L4>=128,CHOOSE(L4-128+1,C4,D4,E4,F4),L4)),256),D4),IF(J4=14,IF(K4=1,_xlfn.BITAND(D4,(IF(L4>=128,CHOOSE(L4-128+1,C4,D4,E4,F4),L4))),D4),IF(J4=16,IF(K4=1,_xlfn.BITOR(D4,(IF(L4>=128,CHOOSE(L4-128+1,C4,D4,E4,F4),L4))),D4),IF(J4=17,IF(K4=1,_xlfn.BITXOR(D4,(IF(L4>=128,CHOOSE(L4-128+1,C4,D4,E4,F4),L4))),D4),IF(J4=18,IF(1=1,QUOTIENT(C4,(IF(L4>=128,CHOOSE(L4-128+1,C4,D4,E4,F4),L4))),IF(1=3,MOD(C4,(IF(L4>=128,CHOOSE(L4-128+1,C4,D4,E4,F4),L4))),D4)),IF(J4=13,D4,D4)))))))))))))))} -> 5 | E5: {=IF(M4=1,E4,IF(J4=15,E4,IF(J4=1,IF(K4=2,L4,E4),IF(J4=2,IF(K4=2,INDEX(N4:AC4,1,L4+1),E4),IF(J4=4,IF(K4=2,CHOOSE(L4+1,C4,D4,E4,F4),E4),IF(J4=5,IF(K4=2,MOD(E4+L4,256),E4),IF(J4=6,IF(K4=2,MOD(E4+CHOOSE(L4+1,C4,D4,E4,F4),256),E4),IF(J4=7,IF(K4=2,MOD(E4-L4,256),E4),IF(J4=8,IF(K4=2,MOD(E4-CHOOSE(L4+1,C4,D4,E4,F4),256),E4),IF(J4=12,IF(K4=2,MOD(E4*(IF(L4>=128,CHOOSE(L4-128+1,C4,D4,E4,F4),L4)),256),E4),IF(J4=14,IF(K4=2,_xlfn.BITAND(E4,(IF(L4>=128,CHOOSE(L4-128+1,C4,D4,E4,F4),L4))),E4),IF(J4=16,IF(K4=2,_xlfn.BITOR(E4,(IF(L4>=128,CHOOSE(L4-128+1,C4,D4,E4,F4),L4))),E4),IF(J4=17,IF(K4=2,_xlfn.BITXOR(E4,(IF(L4>=128,CHOOSE(L4-128+1,C4,D4,E4,F4),L4))),E4),IF(J4=18,IF(2=1,QUOTIENT(C4,(IF(L4>=128,CHOOSE(L4-128+1,C4,D4,E4,F4),L4))),IF(2=3,MOD(C4,(IF(L4>=128,CHOOSE(L4-128+1,C4,D4,E4,F4),L4))),E4)),IF(J4=13,MOD(E4-1,256),E4)))))))))))))))} -> 0 | F5: {=IF(M4=1,F4,IF(J4=15,F4,IF(J4=1,IF(K4=3,L4,F4),IF(J4=2,IF(K4=3,INDEX(N4:AC4,1,L4+1),F4),IF(J4=4,IF(K4=3,CHOOSE(L4+1,C4,D4,E4,F4),F4),IF(J4=5,IF(K4=3,MOD(F4+L4,256),F4),IF(J4=6,IF(K4=3,MOD(F4+CHOOSE(L4+1,C4,D4,E4,F4),256),F4),IF(J4=7,IF(K4=3,MOD(F4-L4,256),F4),IF(J4=8,IF(K4=3,MOD(F4-CHOOSE(L4+1,C4,D4,E4,F4),256),F4),IF(J4=12,IF(K4=3,MOD(F4*(IF(L4>=128,CHOOSE(L4-128+1,C4,D4,E4,F4),L4)),256),F4),IF(J4=14,IF(K4=3,_xlfn.BITAND(F4,(IF(L4>=128,CHOOSE(L4-128+1,C4,D4,E4,F4),L4))),F4),IF(J4=16,IF(K4=3,_xlfn.BITOR(F4,(IF(L4>=128,CHOOSE(L4-128+1,C4,D4,E4,F4),L4))),F4),IF(J4=17,IF(K4=3,_xlfn.BITXOR(F4,(IF(L4>=128,CHOOSE(L4-128+1,C4,D4,E4,F4),L4))),F4),IF(J4=18,IF(3=1,QUOTIENT(C4,(IF(L4>=128,CHOOSE(L4-128+1,C4,D4,E4,F4),L4))),IF(3=3,MOD(C4,(IF(L4>=128,CHOOSE(L4-128+1,C4,D4,E4,F4),L4))),F4)),IF(J4=13,F4,F4)))))))))))))))} -> 0 | G5: =IF(M4=1,G4,IF(OR(J4=5,J4=6,J4=7,J4=8),IF(IF(J4=5,MOD(CHOOSE(K4+1,C4,D4,E4,F4)+L4,256),IF(J4=6,MOD(CHOOSE(K4+1,C4,D4,E4,F4)+CHOOSE(L4+1,C4,D4,E4,F4),256),IF(J4=7,MOD(CHOOSE(K4+1,C4,D4,E4,F4)-L4,256),MOD(CHOOSE(K4+1,C4,D4,E4,F4)-CHOOSE(L4+1,C4,D4,E4,F4),256))))=0,1,0),G4)) -> 0 | H5: =IF(M4=1,H4,IF(J4=5,IF(CHOOSE(K4+1,C4,D4,E4,F4)+L4>255,1,0),IF(J4=6,IF(CHOOSE(K4+1,C4,D4,E4,F4)+CHOOSE(L4+1,C4,D4,E4,F4)>255,1,0),IF(J4=7,IF(CHOOSE(K4+1,C4,D4,E4,F4)<L4,1,0),IF(J4=8,IF(CHOOSE(K4+1,C4,D4,E4,F4)<CHOOSE(L4+1,C4,D4,E4,F4),1,0),H4))))) -> 0 | I5: =IF(M4=1,I4,IF(OR(J4=5,J4=6,J4=7,J4=8),IF(IF(J4=5,MOD(CHOOSE(K4+1,C4,D4,E4,F4)+L4,256),IF(J4=6,MOD(CHOOSE(K4+1,C4,D4,E4,F4)+CHOOSE(L4+1,C4,D4,E4,F4),256),IF(J4=7,MOD(CHOOSE(K4+1,C4,D4,E4,F4)-L4,256),MOD(CHOOSE(K4+1,C4,D4,E4,F4)-CHOOSE(L4+1,C4,D4,E4,F4),256))))>=128,1,0),I4)) -> 0 | J5: {=INDEX(PROGRAM!$E$2:$E$257, B5+1)} -> 3 | K5: {=INDEX(PROGRAM!$F$2:$F$257, B5+1)} -> 1 | L5: {=INDEX(PROGRAM!$G$2:$G$257, B5+1)} -> 0 | M5: =IF(M4=1,1,IF(J4=15,1,0)) -> 0 | N5: =IF(M4=1,N4,IF(J4=3,IF(K4=0,C4,N4),N4)) -> 0 | O5: =IF(M4=1,O4,IF(J4=3,IF(K4=1,C4,O4),O4)) -> 36 | P5: =IF(M4=1,P4,IF(J4=3,IF(K4=2,C4,P4),P4)) -> 15 | Q5: =IF(M4=1,Q4,IF(J4=3,IF(K4=3,C4,Q4),Q4)) -> 0 | R5: =IF(M4=1,R4,IF(J4=3,IF(K4=4,C4,R4),R4)) -> 0 | S5: =IF(M4=1,S4,IF(J4=3,IF(K4=5,C4,S4),S4)) -> 0 | T5: =IF(M4=1,T4,IF(J4=3,IF(K4=6,C4,T4),T4)) -> 0 | U5: =IF(M4=1,U4,IF(J4=3,IF(K4=7,C4,U4),U4)) -> 5 | V5: =IF(M4=1,V4,IF(J4=3,IF(K4=8,C4,V4),V4)) -> 0 | W5: =IF(M4=1,W4,IF(J4=3,IF(K4=9,C4,W4),W4)) -> 0 | X5: =IF(M4=1,X4,IF(J4=3,IF(K4=10,C4,X4),X4)) -> 3 | Y5: =IF(M4=1,Y4,IF(J4=3,IF(K4=11,C4,Y4),Y4)) -> 0 | Z5: =IF(M4=1,Z4,IF(J4=3,IF(K4=12,C4,Z4),Z4)) -> 0 | AA5: =IF(M4=1,AA4,IF(J4=3,IF(K4=13,C4,AA4),AA4)) -> 0 | AB5: =IF(M4=1,AB4,IF(J4=3,IF(K4=14,C4,AB4),AB4)) -> 0 | AC5: =IF(M4=1,AC4,IF(J4=3,IF(K4=15,C4,AC4),AC4)) -> 0
